Workbook

Sheet PRODUCTO NACIONAL
A1: INSUMOS
L2: 0.04 | N2: 1.15
A3: ID | B3: TEXTILERA | C3: TIPO | D3: ANCHO | E3: TUB./ABIERTA | F3: DESCRIPCION | G3: UNIDAD | H3: RINDE | I3: CANTIDAD METROS/KILO | J3: PRECIO UNITARIO | K3: VALOR | L3: DESCUENTO | M3: SUBTOTAL | N3: IVA 15% | O3: COSTO/kilo | P3: COSTO UNIDAD KL + TRANSPORTE | Q3: COSTO X Metro + TRANSPORTE | R3: SUMINISTROS YUNPAR | S3: UNIDAD HOMOLOGADAS | T3: PVP/metro | U3: PVP KILO|PROMO | V3: PVP|DOCENA |X4 | W3: PVP|UNIDAD
A4: M1 | B4: BUENAÑO | C4: TELA | D4: 1.5 | E4: ABIERTA | F4: NYLON | G4: METRO | I4: 100 | J4: 1.3826 | K4: =+I4*J4 -> 138.26 | L4: 0 | M4: =+K4-L4 -> 138.26 | N4: =+M4*$N$2 -> 158.999 | Q4: =(+N4/I4)+0.2 -> 1.78999 | R4: =+Q4 -> 1.78999 | S4: METRO | W4: 2.5 | X4: =+IF(W4<Q4,"ERROR","")
A5: M2 | B5: NILOTEX | C5: CORDON | D5: 20mm | E5: NORMAL | F5: CORDON POLI RIGIDO UMBRO 20mm COLORES | G5: CARRETE | H5: 100 | I5: 5 | J5: 4 | K5: =+I5*J5 -> 20 | M5: =+K5-L5 -> 20 | N5: =+M5*$N$2 -> 23 | P5: =(+N5/I5)+2 -> 6.6 | Q5: =(+P5/H5) -> 0.066 | R5: =+Q5 -> 0.066 | S5: CARRETE | T5: 0.2 | U5: 7.5 | V5: =+U5+0.2 -> 7.7 | W5: =+V5+0.1 -> 7.8 | X5: =+IF(W5<P5,"ERROR","")
A6: M3 | B6: YUNPAR | C6: TINTA | F6: Tinta Jaz Negra | G6: LITRO | I6: 59 | J6: 10.27 | N6: =+J6*1.15 -> 11.8105 | P6: =+N6 -> 11.8105 | R6: =+U6 -> 27 | S6: LITRO | U6: 27 | V6: =+U6+1 -> 28 | W6: =+V6+2 -> 30 | X6: =+IF(U6<P6,"ERROR","")
A7: M4 | B7: YUNPAR | C7: PAPEL | D7: 1.62X200 | E7: ROLLO | F7: Papel de Sublimación 1.62mx200mx70g | G7: ROLLO | I7: 13 | J7: 49.61 | M7: =+I7*J7 -> 644.93 | N7: =+M7*1.15 -> 741.6695 | P7: =+N7/I7 -> 57.0515 | R7: =+U7 -> 64 | S7: ROLLO | U7: 64 | V7: =+U7+1 -> 65 | W7: =+V7+2 -> 67 | X7: =+IF(U7<P7,"ERROR","")
A8: M5 | B8: YUNPAR | C8: PAPEL | D8: 1.62X100 | E8: ROLLO | F8: Papel de Sublimación 1.62mx100mx90g | G8: ROLLO | I8: 62 | J8: 31.94 | M8: =+I8*J8 -> 1980.28 | N8: =+M8*1.15 -> 2277.322 | P8: =+N8/I8 -> 36.731 | R8: =+U8 -> 48 | S8: ROLLO | U8: 48 | V8: =+U8+1 -> 49 | W8: =+V8+1 -> 50 | X8: =+IF(U8<P8,"ERROR","")
A9: M6 | B9: YUNPAR | C9: PAPEL | D9: 1.12X100 | E9: ROLLO | F9: Papel de Sublimación 1.12mx100mx90g | G9: ROLLO | I9: 84 | J9: 22.05 | M9: =+I9*J9 -> 1852.2 | N9: =+M9*1.15 -> 2130.03 | P9: =+N9/I9 -> 25.3575 | R9: =+U9 -> 30 | S9: ROLLO | U9: 30 | V9: =+U9+1 -> 31 | W9: =+V9+2 -> 33 | X9: =+IF(U9<P9,"ERROR","")
A10: M7 | B10: CHINA | C10: CABEZAL | F10: CABEZAL EPSON PLOTTER 1 | G10: UNIDAD | I10: 1 | J10: 4.11 | N10: =+J10*1.15 -> 4.7265 | P10: =+N10 -> 4.7265 | R10: =+P10 -> 4.7265 | S10: UNIDAD
A11: M8 | B11: LOCAL | C11: CINTA | F11: CINTA DE PAPEL | G11: UNIDAD | I11: 1 | J11: 1 | N11: =+J11*1.15 -> 1.15 | P11: =+N11+0.5 -> 1.65 | R11: =+P11 -> 1.65 | S11: UNIDAD
A12: M9 | B12: LOCAL | C12: DAMPERS | F12: DAMPERS | G12: UNIDAD | I12: 1 | J12: 13.5 | N12: =+J12*1.15 -> 15.525 | P12: =+N12+5 -> 20.525 | R12: =+P12 -> 20.525 | S12: UNIDAD
A13: M10 | B13: YUNPAR | C13: PAPEL | D13: 1.8X200 | F13: Papel de Sublimación 1.80mx200mx70g | G13: ROLLO | I13: 90 | J13: 65.459778 | M13: =+I13*J13 -> 5891.38 | N13: =+M13*1.15 -> 6775.087 | P13: =+N13/I13 -> 75.278744 | R13: =+U13 -> 80 | S13: ROLLO | U13: 80 | V13: =+U13+1 -> 81 | W13: =+V13+2 -> 83 | X13: =+IF(U13<P13,"ERROR","") | AO13: CORDON POLI RIGIDO UMBRO 20mm COLORES
A14: M11 | B14: YUNPAR | C14: IMPRESIÓN | D14: 1.8 | E14: ROLLO | F14: IMPRESIÓN SIN DISEÑO, ANCHO 1.8X90gsm | G14: METRO | I14: 1 | J14: =[1]APU3!$C$3 -> 1.3879841 | N14: =+J14 -> 1.3879841 | R14: =+N14 -> 1.3879841 | S14: METRO | U14: 3.25 | V14: =+U14+0.15 -> 3.4 | W14: =+V14+0.1 -> 3.5 | X14: =+IF(U14<N14,"ERROR","")
A15: M12 | B15: EL BARATA | C15: TELA | D15: 1.5 | E15: ABIERTA | F15: LINO JARUBA | G15: METRO | I15: 100 | J15: 1.47 | K15: =+I15*J15 -> 147 | M15: =+K15-L15 -> 147 | N15: =+M15*$N$2 -> 169.05 | Q15: =(+N15/I15)+0.2 -> 1.8905 | R15: =+Q15 -> 1.8905 | S15: METRO | W15: 3 | X15: =+IF(W15<Q15,"ERROR","")
A16: M13 | B16: YUNPAR | C16: SESGO | D16: 1.2 | E16: TUBULAR | F16: SESGO ANCHO CUELLO|SISA EN TELA ERNEST 1.7 ABIERTA | G16: METRO | I16: 1 | J16: =Q17+1.5 -> 2.9285714 | K16: =+I16*J16 -> 2.9285714 | N16: =+K16*1.15 -> 3.3678571 | Q16: =+N16 -> 3.3678571 | R16: =+Q16 -> 3.3678571 | S16: METRO | T16: 5 | U16: 4.8 | V16: =+U16+0.1 -> 4.9 | W16: =+V16+0.1 -> 5 | X16: =+IF(U16<Q16,"ERROR","")
A17: M14 | B17: YUNPAR | C17: TELA | D17: 1.7 | E17: ABIERTA | F17: D2002 Rollo Ernest 1.70m x 140gr | G17: ROLLO | H17: 4.2 | I17: 25 | J17: 4.25 | N17: =+J17*1.15 -> 4.8875 | P17: =+N17 -> 4.8875 | Q17: =+U17/H17 -> 1.4285714 | R17: =+Q17 -> 1.4285714 | S17: ROLLO | U17: 6 | V17: =+U17+0.5 -> 6.5 | W17: =+V17+0.25 -> 6.75 | X17: =+IF(U17<N17,"ERROR","")
A18: M15 | B18: YUNPAR | C18: TELA | D18: 1.7 | E18: ABIERTA | F18: D2006 Rollo Panal 1.70m x 160gr | G18: ROLLO | H18: 3.67 | I18: 25 | J18: 4.27 | N18: =+J18*1.15 -> 4.9105 | P18: =+N18 -> 4.9105 | Q18: =+U18/H18 -> 1.6348774 | R18: =+Q18 -> 1.6348774 | S18: ROLLO | U18: 6 | V18: =+U18+0.5 -> 6.5 | W18: =+V18+0.25 -> 6.75 | X18: =+IF(U18<N18,"ERROR","")
A19: M16 | B19: YUNPAR | C19: TELA | D19: 1.7 | E19: ABIERTA | F19: D2003 Rollo Pike Deportivo 1.70m x 160gr | G19: ROLLO | H19: 3.92 | I19: 25 | J19: 4.21 | N19: =+J19*1.15 -> 4.8415 | P19: =+N19 -> 4.8415 | Q19: =+U19/H19 -> 1.5306122 | R19: =+Q19 -> 1.5306122 | S19: ROLLO | U19: 6 | V19: =+U19+0.5 -> 6.5 | W19: =+V19+0.25 -> 6.75 | X19: =+IF(U19<N19,"ERROR","")
A20: M17 | B20: YUNPAR | C20: TELA | D20: 1.8 | E20: ABIERTA | F20: D2008 Rollo Jersy Spandex 1.80m x 275gr | G20: ROLLO | H20: 2.3 | I20: 20 | J20: 5.38 | N20: =+J20*1.15 -> 6.187 | P20: =+N20 -> 6.187 | Q20: =+U20/H20 -> 3.4782609 | R20: =+Q20 -> 3.4782609 | S20: ROLLO | U20: 8 | V20: =+U20+0.5 -> 8.5 | W20: =+V20+0.25 -> 8.75 | X20: =+IF(U20<N20,"ERROR","")
A21: M18 | B21: PADILLA | C21: RIBB | D21: 0.6 | E21: TUBULAR | F21: RIBB 150TEX COLORES| POLIESTER | G21: KILOS | H21: 4.5 | I21: 13.18 | J21: 7.68 | K21: =+I21*J21 -> 101.2224 | L21: =+K21*$L$2 -> 4.048896 | M21: =+K21-L21 -> 97.173504 | N21: =+M21*$N$2 -> 111.74953 | O21: =(+N21/I21)+1 -> 9.47872 | Q21: =+O21/H21 -> 2.1063822 | R21: =+Q21 -> 2.1063822 | S21: KILOS | W21: 3.5
A22: M19 | B22: PADILLA | C22: TELA | D22: 1.2 | E22: TUBULAR | F22: RIVER TEX NEGRO|COLORES | G22: KILOS | H22: 3.8 | I22: 21.36 | J22: 7.39 | K22: =+I22*J22 -> 157.8504 | L22: =+K22*$L$2 -> 6.314016 | M22: =+K22-L22 -> 151.53638 | N22: =+M22*$N$2 -> 174.26684 | O22: =(+N22/I22)+1 -> 9.15856 | Q22: =+O22/H22 -> 2.4101474 | R22: =+Q22 -> 2.4101474 | S22: KILOS | T22: 3.5 | U22: 9.5 | V22: =+U22+0.3 -> 9.8 | W22: =+V22+0.2 -> 10 | X22: =+IF(U22<O22,"ERROR","")
A23: M20 | B23: NILOTEX | C23: ELASTICO | D23: 4cm | E23: normal | F23: ELASTICO LLANO NORMAL 40mm CRUDO 45metros | G23: METRO | H23: 45 | I23: 20 | J23: 4.65 | K23: =+I23*J23 -> 93 | M23: =+K23-L23 -> 93 | N23: =+M23*$N$2 -> 106.95 | P23: =(+N23/I23)+1 -> 6.3475 | Q23: =+P23/H23 -> 0.14105556 | R23: =+Q23 -> 0.14105556 | S23: METRO | T23: 0.25 | W23: 7 | X23: =+IF(W23<P23,"ERROR","")
A24: M21 | B24: MATEW VERA | C24: ETIQUETA | D24: 58cm | F24: ETIQUETAS DTF TALLA 5.5x2cm | G24: METRO | H24: 330 | I24: 1 | J24: 10 | K24: =+I24*J24 -> 10 | L24: =+K24*$L$2 -> 0.4 | M24: =+K24-L24 -> 9.6 | N24: =+M24*$N$2 -> 11.04 | P24: =+Q24/H24 -> 0.048606061 | Q24: =(+N24/I24)+5 -> 16.04 | R24: =+P24 -> 0.048606061 | S24: METRO | W24: =(+Q24+8)-0.04 -> 24 | X24: =+IF(W24<Q24,"ERROR","")
A25: M22 | B25: LOCAL | C25: FUNDAS | E25: TUBO | F25: FUNDAS PARA EMPAQUETAR | G25: UNIDAD | H25: 100 | I25: 1 | J25: 0.02635 | K25: =+I25*J25 -> 0.02635 | L25: =+K25*$L$2 -> 0.001054 | M25: =+K25-L25 -> 0.025296 | N25: =+M25*$N$2 -> 0.0290904 | O25: =+N25/I25 -> 0.0290904 | P25: =(+N25)+0.02 -> 0.0490904 | R25: =+P25 -> 0.0490904 | S25: UNIDAD
A26: M23 | B26: GUTMAN | C26: POLIN | E26: DOCENA | F26: POLIN GUTMAN T4-6 |T6-8 | G26: UNIDAD | I26: 36 | J26: 1.2318 | K26: =+I26*J26 -> 44.3448 | L26: 0 | M26: =+K26 -> 44.3448 | N26: =+M26*$N$2 -> 50.99652 | P26: =(+N26/I26)+0.3 -> 1.71657 | R26: =+P26 -> 1.71657 | S26: UNIDAD | V26: 19
A27: M24 | B27: GUTMAN | C27: POLIN | E27: DOCENA | F27: POLIN GUTMAN T8-10 | T10-12 | G27: UNIDAD | I27: 36 | J27: 1.4131 | K27: =+I27*J27 -> 50.8716 | L27: 0 | M27: =+K27 -> 50.8716 | N27: =+M27*$N$2 -> 58.50234 | P27: =(+N27/I27)+0.3 -> 1.925065 | R27: =+P27 -> 1.925065 | S27: UNIDAD | V27: 22
A28: M25 | B28: PADILLA | C28: TELA | D28: 1.2 | E28: TUBULAR | F28: ALGODÓN ARUBA PEI AZUL MARINO| COLORES| BLANCO | G28: KILOS | H28: 2.4 | I28: 24.7 | J28: 10.72 | K28: =+I28*J28 -> 264.784 | L28: 37.07 | M28: =+K28-L28 -> 227.714 | N28: =+M28*$N$2 -> 261.8711 | O28: =(+N28/I28)+1 -> 11.602069 | Q28: =+O28/H28 -> 4.8341953 | R28: =+Q28 -> 4.8341953 | S28: METRO | T28: 6 | U28: 13 | V28: =+U28+0.3 -> 13.3 | W28: =+V28+0.2 -> 13.5 | X28: =+IF(U28<O28,"ERROR","")
A29: M26 | B29: YUNPAR | C29: IMPRESIÓN | D29: 1.12 | F29: IMPRESIÓN SIN DISEÑO, ANCHO 1.12mX90gsm | G29: METRO | I29: 1 | J29: =+[1]APU4!$C$3 -> 0.83972038 | N29: =+J29*1.15 -> 0.96567843 | R29: =+N29 -> 0.96567843 | S29: METRO | U29: 2.5 | V29: =+U29+0.15 -> 2.65 | W29: =+V29+0.1 -> 2.75 | X29: =+IF(U29<N29,"ERROR","")
A30: M27 | B30: DIS.PAU | C30: TELA | D30: 1.5 | E30: ABIERTA | F30: VIOTO PESADA BLANCA|NEGRO|NARANJA FOSFORESCENTE | G30: METRO | I30: 100 | J30: 1.52173 | K30: =+I30*J30 -> 152.173 | L30: 0 | M30: =+K30-L30 -> 152.173 | N30: =+M30*$N$2 -> 174.99895 | Q30: =(+N30/I30)+0.2 -> 1.9499895 | R30: =+Q30 -> 1.9499895 | S30: METRO | W30: 3 | X30: =+IF(W30<Q30,"ERROR","")
A31: M28 | B31: BUENAÑO | C31: TELA | D31: 1.5 | E31: ABIERTA | F31: PRADA LISA | G31: METRO | I31: 100 | J31: 2.08 | K31: =+I31*J31 -> 208 | L31: 6.24 | M31: =+K31-L31 -> 201.76 | N31: =+M31*$N$2 -> 232.024 | Q31: =(+N31/I31)+0.2 -> 2.52024 | R31: =+Q31 -> 2.52024 | S31: METRO | W31: 3.5 | X31: =+IF(W31<Q31,"ERROR","")
A32: M29 | B32: LA CASA DEL CIERRE | C32: CIERRE | F32: CIERRE POLIESTER 5 DESPLEGABLE 80CM SENCILLO | G32: UNIDAD | I32: 100 | J32: 0.31304 | K32: =+I32*J32 -> 31.304 | M32: =+K32 -> 31.304 | N32: =+M32*$N$2 -> 35.9996 | P32: =(+N32/I32)+0.1 -> 0.459996 | R32: =+P32 -> 0.459996 | S32: UNIDAD | W32: 1.25 | X32: =+IF(W32<P32,"ERROR","")
A33: M30 | B33: YOMMI | C33: BORDADO | F33: BORDADO CARMEN MORA ESPALDA | G33: UNIDAD | I33: 1 | J33: 2 | N33: =+J33*1.15 -> 2.3 | P33: =+N33+0.2 -> 2.5 | R33: =+P33 -> 2.5 | S33: UNIDAD
A34: M31 | B34: TOLEDO | C34: GAFETE | F34: TIRA DE GAFETE #3 X 24UNI. | G34: UNIDAD | H34: =24*3 -> 72 | I34: 3 | J34: 1 | K34: =+I34*J34 -> 3 | M34: =+K34 -> 3 | N34: =+M34*1.15 -> 3.45 | P34: =(+N34/H34)+0.03 -> 0.077916667 | R34: =+P34 -> 0.077916667 | S34: UNIDAD
A35: M32 | B35: YUNPAR | C35: IMPRESIÓN | D35: 1.62 | F35: IMPRESIÓN SIN DISEÑO, ANCHO 1.62mX70gsm | G35: METRO | I35: 1 | J35: =[1]APU1!$C$3 -> 0.97304719 | N35: =+J35*1.15 -> 1.1190043 | R35: =+N35 -> 1.1190043 | S35: METRO | U35: 3.1 | V35: =+U35+0.15 -> 3.25 | W35: =+V35+0.1 -> 3.35 | X35: =+IF(U35<N35,"ERROR","")
A36: M33 | B36: YUNPAR | C36: IMPRESIÓN | D36: 1.62 | F36: IMPRESIÓN SIN DISEÑO ANCHO 1.62m x 90gsm | G36: METRO | I36: 1 | J36: =[1]APU2!$C$3 -> 1.1330472 | N36: =+J36*1.15 -> 1.3030043 | R36: =+N36 -> 1.3030043 | S36: METRO | U36: 3.25 | V36: =+U36+0.15 -> 3.4 | W36: =+V36+0.1 -> 3.5 | X36: =+IF(U36<N36,"ERROR","")
A37: M34 | B37: LIRA | C37: TELA | D37: 1.5 | E37: ABIERTA | F37: PRADA ROMBOS|CUADROS | G37: METRO | I37: 37 | J37: 2.7027 | K37: =+I37*J37 -> 99.9999 | L37: 0 | M37: =+K37-L37 -> 99.9999 | N37: =+M37*$N$2 -> 114.99988 | Q37: =(+N37/I37)+0.2 -> 3.308105 | R37: =+Q37 -> 3.308105 | S37: METRO | W37: 4 | X37: =+IF(W37<Q37,"ERROR","")
A38: M35 | B38: BUENAÑO | C38: TELA | D38: 1.5 | E38: ABIERTA | F38: NICO SPORT|BLANCO | G38: METRO | I38: 100 | J38: 1.84 | K38: =+I38*J38 -> 184 | L38: 0 | M38: =+K38-L38 -> 184 | N38: =+M38*$N$2 -> 211.6 | Q38: =(+N38/I38)+0.2 -> 2.316 | R38: =+Q38 -> 2.316 | S38: METRO | W38: 4 | X38: =+IF(W38<Q38,"ERROR","")
A39: M36 | B39: MARIA RIVERA | C39: TELA | D39: 1.5 | E39: ABIERTA | F39: Rollo de Galeon 150 ancho | G39: METRO | I39: =20*50 -> 1000 | J39: 0.5 | K39: =+I39*J39 -> 500 | L39: 0 | M39: =+K39-L39 -> 500 | N39: =+M39*$N$2 -> 575 | Q39: =(+N39/I39)+0.2 -> 0.775 | R39: =+Q39 -> 0.775 | S39: METRO | W39: 1.5 | X39: =+IF(W39<Q39,"ERROR","")
A40: M37 | B40: BUENAÑO | C40: TELA | D40: 1.8 | E40: ABIERTA | F40: MURRAY|BLANCA | G40: KILOS | H40: 3.8 | I40: 121.24 | J40: 6.74 | K40: =+I40*J40 -> 817.1576 | L40: 8.17 | M40: =+K40-L40 -> 808.9876 | N40: =+M40*$N$2 -> 930.33574 | O40: =(+N40/I40)+1 -> 8.6735049 | Q40: =+O40/H40 -> 2.2825013 | R40: =+Q40 -> 2.2825013 | S40: METRO | T40: 3.5 | U40: 9.25 | V40: =+U40+0.3 -> 9.55 | W40: =+V40+0.2 -> 9.75 | X40: =+IF(U40<O40,"ERROR","")
...

Sheet PVP
A1: PVP COSTO DE INSUMOS
A2: ='PRODUCTO NACIONAL'!A3 -> ID | B2: NN | C2: =+'PRODUCTO NACIONAL'!C3 -> TIPO | D2: =+'PRODUCTO NACIONAL'!D3 -> ANCHO | E2: =+'PRODUCTO NACIONAL'!H3 -> RINDE | F2: ='PRODUCTO NACIONAL'!F3 -> DESCRIPCION | G2: =+'PRODUCTO NACIONAL'!E3 -> TUB./ABIERTA | H2: ='PRODUCTO NACIONAL'!G3 -> UNIDAD | I2: ='PRODUCTO NACIONAL'!T3 -> PVP/metro | J2: ='PRODUCTO NACIONAL'!U3 -> PVP KILO|PROMO | K2: ='PRODUCTO NACIONAL'!V3 -> PVP|DOCENA |X4 | L2: ='PRODUCTO NACIONAL'!W3 -> PVP|UNIDAD
A3: =IF('PRODUCTO NACIONAL'!A28<>"",'PRODUCTO NACIONAL'!A28,"") -> M25 | B3: ALGODÓN 1.2 | C3: =IF('PRODUCTO NACIONAL'!C28<>"",'PRODUCTO NACIONAL'!C28,"") -> TELA | D3: =IF('PRODUCTO NACIONAL'!D28<>"",'PRODUCTO NACIONAL'!D28,"") -> 1.2 | E3: =IF('PRODUCTO NACIONAL'!H28<>"",'PRODUCTO NACIONAL'!H28,"") -> 2.4 | F3: =IF('PRODUCTO NACIONAL'!F28<>"",'PRODUCTO NACIONAL'!F28,"") -> ALGODÓN ARUBA PEI AZUL MARINO| COLORES| BLANCO | G3: =IF('PRODUCTO NACIONAL'!E28<>"",'PRODUCTO NACIONAL'!E28,"") -> TUBULAR | H3: =IF('PRODUCTO NACIONAL'!G28<>"",'PRODUCTO NACIONAL'!G28,"") -> KILOS | I3: =IF('PRODUCTO NACIONAL'!T28<>"",'PRODUCTO NACIONAL'!T28,"") -> 6 | J3: =IF('PRODUCTO NACIONAL'!U28<>"",'PRODUCTO NACIONAL'!U28,"") -> 13 | K3: =IF('PRODUCTO NACIONAL'!V28<>"",'PRODUCTO NACIONAL'!V28,"") -> 13.3 | L3: =IF('PRODUCTO NACIONAL'!W28<>"",'PRODUCTO NACIONAL'!W28,"") -> 13.5
A4: =IF('PRODUCTO NACIONAL'!A65<>"",'PRODUCTO NACIONAL'!A65,"") -> M62 | B4: ALGODÓN 90cm | C4: =IF('PRODUCTO NACIONAL'!C65<>"",'PRODUCTO NACIONAL'!C65,"") -> TELA | D4: =IF('PRODUCTO NACIONAL'!D65<>"",'PRODUCTO NACIONAL'!D65,"") -> 0.86 | E4: =IF('PRODUCTO NACIONAL'!H65<>"",'PRODUCTO NACIONAL'!H65,"") -> 3 | F4: =IF('PRODUCTO NACIONAL'!F65<>"",'PRODUCTO NACIONAL'!F65,"") -> ALGODÓN DENISSE PEI AZUL MARINO |COLORES | BLANCO | G4: =IF('PRODUCTO NACIONAL'!E65<>"",'PRODUCTO NACIONAL'!E65,"") -> TUBULAR | H4: =IF('PRODUCTO NACIONAL'!G65<>"",'PRODUCTO NACIONAL'!G65,"") -> KILOS | I4: =IF('PRODUCTO NACIONAL'!T65<>"",'PRODUCTO NACIONAL'!T65,"") -> 5 | J4: =IF('PRODUCTO NACIONAL'!U65<>"",'PRODUCTO NACIONAL'!U65,"") -> 12.25 | K4: =IF('PRODUCTO NACIONAL'!V65<>"",'PRODUCTO NACIONAL'!V65,"") -> 12.55 | L4: =IF('PRODUCTO NACIONAL'!W65<>"",'PRODUCTO NACIONAL'!W65,"") -> 12.75
A5: =IF('PRODUCTO NACIONAL'!A63<>"",'PRODUCTO NACIONAL'!A63,"") -> M60 | B5: INTERLOCK SPUN | C5: =IF('PRODUCTO NACIONAL'!C63<>"",'PRODUCTO NACIONAL'!C63,"") -> TELA | D5: =IF('PRODUCTO NACIONAL'!D63<>"",'PRODUCTO NACIONAL'!D63,"") -> 1.1 | E5: =IF('PRODUCTO NACIONAL'!H63<>"",'PRODUCTO NACIONAL'!H63,"") -> 2.1 | F5: =IF('PRODUCTO NACIONAL'!F63<>"",'PRODUCTO NACIONAL'!F63,"") -> ALGODÓN INTERLOCK SPUN 30 BLANCO FROZEN | G5: =IF('PRODUCTO NACIONAL'!E63<>"",'PRODUCTO NACIONAL'!E63,"") -> TUBULAR | H5: =IF('PRODUCTO NACIONAL'!G63<>"",'PRODUCTO NACIONAL'!G63,"") -> KILOS | I5: =IF('PRODUCTO NACIONAL'!T63<>"",'PRODUCTO NACIONAL'!T63,"") -> 6 | J5: =IF('PRODUCTO NACIONAL'!U63<>"",'PRODUCTO NACIONAL'!U63,"") -> 12 | K5: =IF('PRODUCTO NACIONAL'!V63<>"",'PRODUCTO NACIONAL'!V63,"") -> 12.3 | L5: =IF('PRODUCTO NACIONAL'!W63<>"",'PRODUCTO NACIONAL'!W63,"") -> 12.5
A6: =IF('PRODUCTO NACIONAL'!A64<>"",'PRODUCTO NACIONAL'!A64,"") -> M61 | B6: SPUN MEDIO | C6: =IF('PRODUCTO NACIONAL'!C64<>"",'PRODUCTO NACIONAL'!C64,"") -> TELA | D6: =IF('PRODUCTO NACIONAL'!D64<>"",'PRODUCTO NACIONAL'!D64,"") -> 1.2 | E6: =IF('PRODUCTO NACIONAL'!H64<>"",'PRODUCTO NACIONAL'!H64,"") -> 2.4 | F6: =IF('PRODUCTO NACIONAL'!F64<>"",'PRODUCTO NACIONAL'!F64,"") -> INTERLOCK 40 SPUN 1.2 BLANCO FROZEN | G6: =IF('PRODUCTO NACIONAL'!E64<>"",'PRODUCTO NACIONAL'!E64,"") -> TUBULAR | H6: =IF('PRODUCTO NACIONAL'!G64<>"",'PRODUCTO NACIONAL'!G64,"") -> KILOS | I6: =IF('PRODUCTO NACIONAL'!T64<>"",'PRODUCTO NACIONAL'!T64,"") -> 5.5 | J6: =IF('PRODUCTO NACIONAL'!U64<>"",'PRODUCTO NACIONAL'!U64,"") -> 12 | K6: =IF('PRODUCTO NACIONAL'!V64<>"",'PRODUCTO NACIONAL'!V64,"") -> 12.3 | L6: =IF('PRODUCTO NACIONAL'!W64<>"",'PRODUCTO NACIONAL'!W64,"") -> 12.5
A7: =IF('PRODUCTO NACIONAL'!A66<>"",'PRODUCTO NACIONAL'!A66,"") -> M63 | B7: CHELSEA 1.2 | C7: =IF('PRODUCTO NACIONAL'!C66<>"",'PRODUCTO NACIONAL'!C66,"") -> TELA | D7: =IF('PRODUCTO NACIONAL'!D66<>"",'PRODUCTO NACIONAL'!D66,"") -> 1.2 | E7: =IF('PRODUCTO NACIONAL'!H66<>"",'PRODUCTO NACIONAL'!H66,"") -> 3.3 | F7: =IF('PRODUCTO NACIONAL'!F66<>"",'PRODUCTO NACIONAL'!F66,"") -> CHELSEA MIC NARANJA FOSFORESCENTE | G7: =IF('PRODUCTO NACIONAL'!E66<>"",'PRODUCTO NACIONAL'!E66,"") -> TUBULAR | H7: =IF('PRODUCTO NACIONAL'!G66<>"",'PRODUCTO NACIONAL'!G66,"") -> KILOS | I7: =IF('PRODUCTO NACIONAL'!T66<>"",'PRODUCTO NACIONAL'!T66,"") -> 3.5 | J7: =IF('PRODUCTO NACIONAL'!U66<>"",'PRODUCTO NACIONAL'!U66,"") -> 10.5 | K7: =IF('PRODUCTO NACIONAL'!V66<>"",'PRODUCTO NACIONAL'!V66,"") -> 10.8 | L7: =IF('PRODUCTO NACIONAL'!W66<>"",'PRODUCTO NACIONAL'!W66,"") -> 11
A8: =IF('PRODUCTO NACIONAL'!A15<>"",'PRODUCTO NACIONAL'!A15,"") -> M12 | B8: LINO | C8: =IF('PRODUCTO NACIONAL'!C15<>"",'PRODUCTO NACIONAL'!C15,"") -> TELA | D8: =IF('PRODUCTO NACIONAL'!D15<>"",'PRODUCTO NACIONAL'!D15,"") -> 1.5 | E8: =IF('PRODUCTO NACIONAL'!H15<>"",'PRODUCTO NACIONAL'!H15,"") | F8: =IF('PRODUCTO NACIONAL'!F15<>"",'PRODUCTO NACIONAL'!F15,"") -> LINO JARUBA | G8: =IF('PRODUCTO NACIONAL'!E15<>"",'PRODUCTO NACIONAL'!E15,"") -> ABIERTA | H8: =IF('PRODUCTO NACIONAL'!G15<>"",'PRODUCTO NACIONAL'!G15,"") -> METRO | I8: =IF('PRODUCTO NACIONAL'!T15<>"",'PRODUCTO NACIONAL'!T15,"") | J8: =IF('PRODUCTO NACIONAL'!U15<>"",'PRODUCTO NACIONAL'!U15,"") | K8: =IF('PRODUCTO NACIONAL'!V15<>"",'PRODUCTO NACIONAL'!V15,"") | L8: =IF('PRODUCTO NACIONAL'!W15<>"",'PRODUCTO NACIONAL'!W15,"") -> 3
A9: =IF('PRODUCTO NACIONAL'!A40<>"",'PRODUCTO NACIONAL'!A40,"") -> M37 | B9: MURRAY | C9: =IF('PRODUCTO NACIONAL'!C40<>"",'PRODUCTO NACIONAL'!C40,"") -> TELA | D9: =IF('PRODUCTO NACIONAL'!D40<>"",'PRODUCTO NACIONAL'!D40,"") -> 1.8 | E9: =IF('PRODUCTO NACIONAL'!H40<>"",'PRODUCTO NACIONAL'!H40,"") -> 3.8 | F9: =IF('PRODUCTO NACIONAL'!F40<>"",'PRODUCTO NACIONAL'!F40,"") -> MURRAY|BLANCA | G9: =IF('PRODUCTO NACIONAL'!E40<>"",'PRODUCTO NACIONAL'!E40,"") -> ABIERTA | H9: =IF('PRODUCTO NACIONAL'!G40<>"",'PRODUCTO NACIONAL'!G40,"") -> KILOS | I9: =IF('PRODUCTO NACIONAL'!T40<>"",'PRODUCTO NACIONAL'!T40,"") -> 3.5 | J9: =IF('PRODUCTO NACIONAL'!U40<>"",'PRODUCTO NACIONAL'!U40,"") -> 9.25 | K9: =IF('PRODUCTO NACIONAL'!V40<>"",'PRODUCTO NACIONAL'!V40,"") -> 9.55 | L9: =IF('PRODUCTO NACIONAL'!W40<>"",'PRODUCTO NACIONAL'!W40,"") -> 9.75
A10: =IF('PRODUCTO NACIONAL'!A38<>"",'PRODUCTO NACIONAL'!A38,"") -> M35 | B10: NICO | C10: =IF('PRODUCTO NACIONAL'!C38<>"",'PRODUCTO NACIONAL'!C38,"") -> TELA | D10: =IF('PRODUCTO NACIONAL'!D38<>"",'PRODUCTO NACIONAL'!D38,"") -> 1.5 | E10: =IF('PRODUCTO NACIONAL'!H38<>"",'PRODUCTO NACIONAL'!H38,"") | F10: =IF('PRODUCTO NACIONAL'!F38<>"",'PRODUCTO NACIONAL'!F38,"") -> NICO SPORT|BLANCO | G10: =IF('PRODUCTO NACIONAL'!E38<>"",'PRODUCTO NACIONAL'!E38,"") -> ABIERTA | H10: =IF('PRODUCTO NACIONAL'!G38<>"",'PRODUCTO NACIONAL'!G38,"") -> METRO | I10: =IF('PRODUCTO NACIONAL'!T38<>"",'PRODUCTO NACIONAL'!T38,"") | J10: =IF('PRODUCTO NACIONAL'!U38<>"",'PRODUCTO NACIONAL'!U38,"") | K10: =IF('PRODUCTO NACIONAL'!V38<>"",'PRODUCTO NACIONAL'!V38,"") | L10: =IF('PRODUCTO NACIONAL'!W38<>"",'PRODUCTO NACIONAL'!W38,"") -> 4
A11: =IF('PRODUCTO NACIONAL'!A4<>"",'PRODUCTO NACIONAL'!A4,"") -> M1 | B11: NYLON | C11: =IF('PRODUCTO NACIONAL'!C4<>"",'PRODUCTO NACIONAL'!C4,"") -> TELA | D11: =IF('PRODUCTO NACIONAL'!D4<>"",'PRODUCTO NACIONAL'!D4,"") -> 1.5 | E11: =IF('PRODUCTO NACIONAL'!H4<>"",'PRODUCTO NACIONAL'!H4,"") | F11: =IF('PRODUCTO NACIONAL'!F4<>"",'PRODUCTO NACIONAL'!F4,"") -> NYLON | G11: =IF('PRODUCTO NACIONAL'!E4<>"",'PRODUCTO NACIONAL'!E4,"") -> ABIERTA | H11: =IF('PRODUCTO NACIONAL'!G4<>"",'PRODUCTO NACIONAL'!G4,"") -> METRO | I11: =IF('PRODUCTO NACIONAL'!T4<>"",'PRODUCTO NACIONAL'!T4,"") | J11: =IF('PRODUCTO NACIONAL'!U4<>"",'PRODUCTO NACIONAL'!U4,"") | K11: =IF('PRODUCTO NACIONAL'!V4<>"",'PRODUCTO NACIONAL'!V4,"") | L11: =IF('PRODUCTO NACIONAL'!W4<>"",'PRODUCTO NACIONAL'!W4,"") -> 2.5
A12: =IF('PRODUCTO NACIONAL'!A62<>"",'PRODUCTO NACIONAL'!A62,"") -> M59 | B12: PIKE OSCURO | C12: =IF('PRODUCTO NACIONAL'!C62<>"",'PRODUCTO NACIONAL'!C62,"") -> TELA | D12: =IF('PRODUCTO NACIONAL'!D62<>"",'PRODUCTO NACIONAL'!D62,"") -> 1.2 | E12: =IF('PRODUCTO NACIONAL'!H62<>"",'PRODUCTO NACIONAL'!H62,"") -> 2 | F12: =IF('PRODUCTO NACIONAL'!F62<>"",'PRODUCTO NACIONAL'!F62,"") -> PIKE LACOAST 20 PEI AZUL MARINO| OSCURO | G12: =IF('PRODUCTO NACIONAL'!E62<>"",'PRODUCTO NACIONAL'!E62,"") -> TUBULAR | H12: =IF('PRODUCTO NACIONAL'!G62<>"",'PRODUCTO NACIONAL'!G62,"") -> KILOS | I12: =IF('PRODUCTO NACIONAL'!T62<>"",'PRODUCTO NACIONAL'!T62,"") -> 6.5 | J12: =IF('PRODUCTO NACIONAL'!U62<>"",'PRODUCTO NACIONAL'!U62,"") -> 12 | K12: =IF('PRODUCTO NACIONAL'!V62<>"",'PRODUCTO NACIONAL'!V62,"") -> 12.3 | L12: =IF('PRODUCTO NACIONAL'!W62<>"",'PRODUCTO NACIONAL'!W62,"") -> 12.5
A13: =IF('PRODUCTO NACIONAL'!A61<>"",'PRODUCTO NACIONAL'!A61,"") -> M58 | B13: PIKE CLARO | C13: =IF('PRODUCTO NACIONAL'!C61<>"",'PRODUCTO NACIONAL'!C61,"") -> TELA | D13: =IF('PRODUCTO NACIONAL'!D61<>"",'PRODUCTO NACIONAL'!D61,"") -> 1.2 | E13: =IF('PRODUCTO NACIONAL'!H61<>"",'PRODUCTO NACIONAL'!H61,"") -> 2 | F13: =IF('PRODUCTO NACIONAL'!F61<>"",'PRODUCTO NACIONAL'!F61,"") -> PIKE LACOAST 20 PEI CELESTE| CLARO | G13: =IF('PRODUCTO NACIONAL'!E61<>"",'PRODUCTO NACIONAL'!E61,"") -> TUBULAR | H13: =IF('PRODUCTO NACIONAL'!G61<>"",'PRODUCTO NACIONAL'!G61,"") -> KILOS | I13: =IF('PRODUCTO NACIONAL'!T61<>"",'PRODUCTO NACIONAL'!T61,"") -> 6.5 | J13: =IF('PRODUCTO NACIONAL'!U61<>"",'PRODUCTO NACIONAL'!U61,"") -> 12 | K13: =IF('PRODUCTO NACIONAL'!V61<>"",'PRODUCTO NACIONAL'!V61,"") -> 12.3 | L13: =IF('PRODUCTO NACIONAL'!W61<>"",'PRODUCTO NACIONAL'!W61,"") -> 12.5
A14: =IF('PRODUCTO NACIONAL'!A31<>"",'PRODUCTO NACIONAL'!A31,"") -> M28 | B14: PRADA LISA | C14: =IF('PRODUCTO NACIONAL'!C31<>"",'PRODUCTO NACIONAL'!C31,"") -> TELA | D14: =IF('PRODUCTO NACIONAL'!D31<>"",'PRODUCTO NACIONAL'!D31,"") -> 1.5 | E14: =IF('PRODUCTO NACIONAL'!H31<>"",'PRODUCTO NACIONAL'!H31,"") | F14: =IF('PRODUCTO NACIONAL'!F31<>"",'PRODUCTO NACIONAL'!F31,"") -> PRADA LISA | G14: =IF('PRODUCTO NACIONAL'!E31<>"",'PRODUCTO NACIONAL'!E31,"") -> ABIERTA | H14: =IF('PRODUCTO NACIONAL'!G31<>"",'PRODUCTO NACIONAL'!G31,"") -> METRO | I14: =IF('PRODUCTO NACIONAL'!W31<>"",'PRODUCTO NACIONAL'!W31,"") -> 3.5 | J14: =IF('PRODUCTO NACIONAL'!U31<>"",'PRODUCTO NACIONAL'!U31,"") | K14: =IF('PRODUCTO NACIONAL'!V31<>"",'PRODUCTO NACIONAL'!V31,"") | L14: =IF('PRODUCTO NACIONAL'!W31<>"",'PRODUCTO NACIONAL'!W31,"") -> 3.5
A15: =IF('PRODUCTO NACIONAL'!A37<>"",'PRODUCTO NACIONAL'!A37,"") -> M34 | B15: PRADA ROMBOS | C15: =IF('PRODUCTO NACIONAL'!C37<>"",'PRODUCTO NACIONAL'!C37,"") -> TELA | D15: =IF('PRODUCTO NACIONAL'!D37<>"",'PRODUCTO NACIONAL'!D37,"") -> 1.5 | E15: =IF('PRODUCTO NACIONAL'!H37<>"",'PRODUCTO NACIONAL'!H37,"") | F15: =IF('PRODUCTO NACIONAL'!F37<>"",'PRODUCTO NACIONAL'!F37,"") -> PRADA ROMBOS|CUADROS | G15: =IF('PRODUCTO NACIONAL'!E37<>"",'PRODUCTO NACIONAL'!E37,"") -> ABIERTA | H15: =IF('PRODUCTO NACIONAL'!G37<>"",'PRODUCTO NACIONAL'!G37,"") -> METRO | I15: =IF('PRODUCTO NACIONAL'!T37<>"",'PRODUCTO NACIONAL'!T37,"") | J15: =IF('PRODUCTO NACIONAL'!U37<>"",'PRODUCTO NACIONAL'!U37,"") | K15: =IF('PRODUCTO NACIONAL'!V37<>"",'PRODUCTO NACIONAL'!V37,"") | L15: =IF('PRODUCTO NACIONAL'!W37<>"",'PRODUCTO NACIONAL'!W37,"") -> 4
A16: =IF('PRODUCTO NACIONAL'!A22<>"",'PRODUCTO NACIONAL'!A22,"") -> M19 | B16: RIVER | C16: =IF('PRODUCTO NACIONAL'!C22<>"",'PRODUCTO NACIONAL'!C22,"") -> TELA | D16: =IF('PRODUCTO NACIONAL'!D22<>"",'PRODUCTO NACIONAL'!D22,"") -> 1.2 | E16: =IF('PRODUCTO NACIONAL'!H22<>"",'PRODUCTO NACIONAL'!H22,"") -> 3.8 | F16: =IF('PRODUCTO NACIONAL'!F22<>"",'PRODUCTO NACIONAL'!F22,"") -> RIVER TEX NEGRO|COLORES | G16: =IF('PRODUCTO NACIONAL'!E22<>"",'PRODUCTO NACIONAL'!E22,"") -> TUBULAR | H16: =IF('PRODUCTO NACIONAL'!G22<>"",'PRODUCTO NACIONAL'!G22,"") -> KILOS | I16: =IF('PRODUCTO NACIONAL'!T22<>"",'PRODUCTO NACIONAL'!T22,"") -> 3.5 | J16: =IF('PRODUCTO NACIONAL'!U22<>"",'PRODUCTO NACIONAL'!U22,"") -> 9.5 | K16: =IF('PRODUCTO NACIONAL'!V22<>"",'PRODUCTO NACIONAL'!V22,"") -> 9.8 | L16: =IF('PRODUCTO NACIONAL'!W22<>"",'PRODUCTO NACIONAL'!W22,"") -> 10
A17: =IF('PRODUCTO NACIONAL'!A39<>"",'PRODUCTO NACIONAL'!A39,"") -> M36 | B17: GALEON | C17: =IF('PRODUCTO NACIONAL'!C39<>"",'PRODUCTO NACIONAL'!C39,"") -> TELA | D17: =IF('PRODUCTO NACIONAL'!D39<>"",'PRODUCTO NACIONAL'!D39,"") -> 1.5 | E17: =IF('PRODUCTO NACIONAL'!H39<>"",'PRODUCTO NACIONAL'!H39,"") | F17: =IF('PRODUCTO NACIONAL'!F39<>"",'PRODUCTO NACIONAL'!F39,"") -> Rollo de Galeon 150 ancho | G17: =IF('PRODUCTO NACIONAL'!E39<>"",'PRODUCTO NACIONAL'!E39,"") -> ABIERTA | H17: =IF('PRODUCTO NACIONAL'!G39<>"",'PRODUCTO NACIONAL'!G39,"") -> METRO | I17: =IF('PRODUCTO NACIONAL'!W39<>"",'PRODUCTO NACIONAL'!W39,"") -> 1.5 | J17: =IF('PRODUCTO NACIONAL'!U39<>"",'PRODUCTO NACIONAL'!U39,"") | K17: =IF('PRODUCTO NACIONAL'!V39<>"",'PRODUCTO NACIONAL'!V39,"") | L17: =IF('PRODUCTO NACIONAL'!W39<>"",'PRODUCTO NACIONAL'!W39,"") -> 1.5
A18: =IF('PRODUCTO NACIONAL'!A77<>"",'PRODUCTO NACIONAL'!A77,"") -> M74 | B18: RIBB ACANALADO | C18: =IF('PRODUCTO NACIONAL'!C77<>"",'PRODUCTO NACIONAL'!C77,"") -> RIBB | D18: =IF('PRODUCTO NACIONAL'!D77<>"",'PRODUCTO NACIONAL'!D77,"") -> 50 | E18: =IF('PRODUCTO NACIONAL'!H77<>"",'PRODUCTO NACIONAL'!H77,"") -> 2.5 | F18: =IF('PRODUCTO NACIONAL'!F77<>"",'PRODUCTO NACIONAL'!F77,"") -> Ribb Acanalado color negro POLIALGODON | G18: =IF('PRODUCTO NACIONAL'!E77<>"",'PRODUCTO NACIONAL'!E77,"") -> TUBULAR | H18: =IF('PRODUCTO NACIONAL'!G77<>"",'PRODUCTO NACIONAL'!G77,"") -> KILOS | I18: =IF('PRODUCTO NACIONAL'!W77<>"",'PRODUCTO NACIONAL'!W77,"") -> 7 | J18: =IF('PRODUCTO NACIONAL'!U77<>"",'PRODUCTO NACIONAL'!U77,"") | K18: =IF('PRODUCTO NACIONAL'!V77<>"",'PRODUCTO NACIONAL'!V77,"") | L18: =IF('PRODUCTO NACIONAL'!W77<>"",'PRODUCTO NACIONAL'!W77,"") -> 7
A19: =IF('PRODUCTO NACIONAL'!A78<>"",'PRODUCTO NACIONAL'!A78,"") -> M75 | B19: RIBB LUGANO | C19: =IF('PRODUCTO NACIONAL'!C78<>"",'PRODUCTO NACIONAL'!C78,"") -> RIBB | D19: =IF('PRODUCTO NACIONAL'!D78<>"",'PRODUCTO NACIONAL'!D78,"") -> 50 | E19: =IF('PRODUCTO NACIONAL'!H78<>"",'PRODUCTO NACIONAL'!H78,"") -> 2.5 | F19: =IF('PRODUCTO NACIONAL'!F78<>"",'PRODUCTO NACIONAL'!F78,"") -> Ribb Lugano 100% POLIESTER | G19: =IF('PRODUCTO NACIONAL'!E78<>"",'PRODUCTO NACIONAL'!E78,"") -> TUBULAR | H19: =IF('PRODUCTO NACIONAL'!G78<>"",'PRODUCTO NACIONAL'!G78,"") -> KILOS | I19: =IF('PRODUCTO NACIONAL'!W78<>"",'PRODUCTO NACIONAL'!W78,"") -> 6 | J19: =IF('PRODUCTO NACIONAL'!U78<>"",'PRODUCTO NACIONAL'!U78,"") | K19: =IF('PRODUCTO NACIONAL'!V78<>"",'PRODUCTO NACIONAL'!V78,"") | L19: =IF('PRODUCTO NACIONAL'!W78<>"",'PRODUCTO NACIONAL'!W78,"") -> 6
A20: =IF('PRODUCTO NACIONAL'!A21<>"",'PRODUCTO NACIONAL'!A21,"") -> M18 | B20: RIBB POLIESTER | C20: =IF('PRODUCTO NACIONAL'!C21<>"",'PRODUCTO NACIONAL'!C21,"") -> RIBB | D20: =IF('PRODUCTO NACIONAL'!D21<>"",'PRODUCTO NACIONAL'!D21,"") -> 0.6 | E20: =IF('PRODUCTO NACIONAL'!H21<>"",'PRODUCTO NACIONAL'!H21,"") -> 4.5 | F20: =IF('PRODUCTO NACIONAL'!F21<>"",'PRODUCTO NACIONAL'!F21,"") -> RIBB 150TEX COLORES| POLIESTER | G20: =IF('PRODUCTO NACIONAL'!E21<>"",'PRODUCTO NACIONAL'!E21,"") -> TUBULAR | H20: =IF('PRODUCTO NACIONAL'!G21<>"",'PRODUCTO NACIONAL'!G21,"") -> KILOS | I20: =IF('PRODUCTO NACIONAL'!W21<>"",'PRODUCTO NACIONAL'!W21,"") -> 3.5 | J20: =IF('PRODUCTO NACIONAL'!U21<>"",'PRODUCTO NACIONAL'!U21,"") | K20: =IF('PRODUCTO NACIONAL'!V21<>"",'PRODUCTO NACIONAL'!V21,"") | L20: =IF('PRODUCTO NACIONAL'!W21<>"",'PRODUCTO NACIONAL'!W21,"") -> 3.5
A21: M78 | B21: DURAZNO | C21: =IF('PRODUCTO NACIONAL'!C82<>"",'PRODUCTO NACIONAL'!C82,"") -> TELA | D21: =IF('PRODUCTO NACIONAL'!D82<>"",'PRODUCTO NACIONAL'!D82,"") -> 1.8 | E21: =IF('PRODUCTO NACIONAL'!H82<>"",'PRODUCTO NACIONAL'!H82,"") | F21: =IF('PRODUCTO NACIONAL'!F82<>"",'PRODUCTO NACIONAL'!F82,"") -> PIEL DE DURAZNO | G21: =IF('PRODUCTO NACIONAL'!E82<>"",'PRODUCTO NACIONAL'!E82,"") -> ABIERTA | H21: =IF('PRODUCTO NACIONAL'!G82<>"",'PRODUCTO NACIONAL'!G82,"") -> METRO | I21: =IF('PRODUCTO NACIONAL'!W82<>"",'PRODUCTO NACIONAL'!W82,"") -> 3.5 | J21: =IF('PRODUCTO NACIONAL'!U82<>"",'PRODUCTO NACIONAL'!U82,"") -> 2.5 | K21: =IF('PRODUCTO NACIONAL'!V82<>"",'PRODUCTO NACIONAL'!V82,"") | L21: =IF('PRODUCTO NACIONAL'!W82<>"",'PRODUCTO NACIONAL'!W82,"") -> 3.5
J22: MAS DE 10 | K22: MAS DE 3 | L22: ROLLO
A23: =IF('PRODUCTO NACIONAL'!A17<>"",'PRODUCTO NACIONAL'!A17,"") -> M14 | B23: ERNEST | C23: =IF('PRODUCTO NACIONAL'!C17<>"",'PRODUCTO NACIONAL'!C17,"") -> TELA | D23: =IF('PRODUCTO NACIONAL'!D17<>"",'PRODUCTO NACIONAL'!D17,"") -> 1.7 | E23: =IF('PRODUCTO NACIONAL'!H17<>"",'PRODUCTO NACIONAL'!H17,"") -> 4.2 | F23: =IF('PRODUCTO NACIONAL'!F17<>"",'PRODUCTO NACIONAL'!F17,"") -> D2002 Rollo Ernest 1.70m x 140gr | G23: =IF('PRODUCTO NACIONAL'!E17<>"",'PRODUCTO NACIONAL'!E17,"") -> ABIERTA | H23: =IF('PRODUCTO NACIONAL'!G17<>"",'PRODUCTO NACIONAL'!G17,"") -> ROLLO | I23: =IF('PRODUCTO NACIONAL'!T17<>"",'PRODUCTO NACIONAL'!T17,"") | J23: =IF('PRODUCTO NACIONAL'!U17<>"",'PRODUCTO NACIONAL'!U17,"") -> 6 | K23: =IF('PRODUCTO NACIONAL'!V17<>"",'PRODUCTO NACIONAL'!V17,"") -> 6.5 | L23: =IF('PRODUCTO NACIONAL'!W17<>"",'PRODUCTO NACIONAL'!W17,"") -> 6.75
A24: =IF('PRODUCTO NACIONAL'!A20<>"",'PRODUCTO NACIONAL'!A20,"") -> M17 | B24: JERSEY | C24: =IF('PRODUCTO NACIONAL'!C20<>"",'PRODUCTO NACIONAL'!C20,"") -> TELA | D24: =IF('PRODUCTO NACIONAL'!D20<>"",'PRODUCTO NACIONAL'!D20,"") -> 1.8 | E24: =IF('PRODUCTO NACIONAL'!H20<>"",'PRODUCTO NACIONAL'!H20,"") -> 2.3 | F24: =IF('PRODUCTO NACIONAL'!F20<>"",'PRODUCTO NACIONAL'!F20,"") -> D2008 Rollo Jersy Spandex 1.80m x 275gr | G24: =IF('PRODUCTO NACIONAL'!E20<>"",'PRODUCTO NACIONAL'!E20,"") -> ABIERTA | H24: =IF('PRODUCTO NACIONAL'!G20<>"",'PRODUCTO NACIONAL'!G20,"") -> ROLLO | I24: =IF('PRODUCTO NACIONAL'!T20<>"",'PRODUCTO NACIONAL'!T20,"") | J24: =IF('PRODUCTO NACIONAL'!U20<>"",'PRODUCTO NACIONAL'!U20,"") -> 8 | K24: =IF('PRODUCTO NACIONAL'!V20<>"",'PRODUCTO NACIONAL'!V20,"") -> 8.5 | L24: =IF('PRODUCTO NACIONAL'!W20<>"",'PRODUCTO NACIONAL'!W20,"") -> 8.75
A25: =IF('PRODUCTO NACIONAL'!A18<>"",'PRODUCTO NACIONAL'!A18,"") -> M15 | B25: PANAL | C25: =IF('PRODUCTO NACIONAL'!C18<>"",'PRODUCTO NACIONAL'!C18,"") -> TELA | D25: =IF('PRODUCTO NACIONAL'!D18<>"",'PRODUCTO NACIONAL'!D18,"") -> 1.7 | E25: =IF('PRODUCTO NACIONAL'!H18<>"",'PRODUCTO NACIONAL'!H18,"") -> 3.67 | F25: =IF('PRODUCTO NACIONAL'!F18<>"",'PRODUCTO NACIONAL'!F18,"") -> D2006 Rollo Panal 1.70m x 160gr | G25: =IF('PRODUCTO NACIONAL'!E18<>"",'PRODUCTO NACIONAL'!E18,"") -> ABIERTA | H25: =IF('PRODUCTO NACIONAL'!G18<>"",'PRODUCTO NACIONAL'!G18,"") -> ROLLO | I25: =IF('PRODUCTO NACIONAL'!T18<>"",'PRODUCTO NACIONAL'!T18,"") | J25: =IF('PRODUCTO NACIONAL'!U18<>"",'PRODUCTO NACIONAL'!U18,"") -> 6 | K25: =IF('PRODUCTO NACIONAL'!V18<>"",'PRODUCTO NACIONAL'!V18,"") -> 6.5 | L25: =IF('PRODUCTO NACIONAL'!W18<>"",'PRODUCTO NACIONAL'!W18,"") -> 6.75
A26: =IF('PRODUCTO NACIONAL'!A19<>"",'PRODUCTO NACIONAL'!A19,"") -> M16 | B26: PIKE DEPORTIVO | C26: =IF('PRODUCTO NACIONAL'!C19<>"",'PRODUCTO NACIONAL'!C19,"") -> TELA | D26: =IF('PRODUCTO NACIONAL'!D19<>"",'PRODUCTO NACIONAL'!D19,"") -> 1.7 | E26: =IF('PRODUCTO NACIONAL'!H19<>"",'PRODUCTO NACIONAL'!H19,"") -> 3.92 | F26: =IF('PRODUCTO NACIONAL'!F19<>"",'PRODUCTO NACIONAL'!F19,"") -> D2003 Rollo Pike Deportivo 1.70m x 160gr | G26: =IF('PRODUCTO NACIONAL'!E19<>"",'PRODUCTO NACIONAL'!E19,"") -> ABIERTA | H26: =IF('PRODUCTO NACIONAL'!G19<>"",'PRODUCTO NACIONAL'!G19,"") -> ROLLO | I26: =IF('PRODUCTO NACIONAL'!T19<>"",'PRODUCTO NACIONAL'!T19,"") | J26: =IF('PRODUCTO NACIONAL'!U19<>"",'PRODUCTO NACIONAL'!U19,"") -> 6 | K26: =IF('PRODUCTO NACIONAL'!V19<>"",'PRODUCTO NACIONAL'!V19,"") -> 6.5 | L26: =IF('PRODUCTO NACIONAL'!W19<>"",'PRODUCTO NACIONAL'!W19,"") -> 6.75
A27: =IF('PRODUCTO NACIONAL'!A42<>"",'PRODUCTO NACIONAL'!A42,"") -> M39 | B27: TAPA | C27: =IF('PRODUCTO NACIONAL'!C42<>"",'PRODUCTO NACIONAL'!C42,"") -> TELA | D27: =IF('PRODUCTO NACIONAL'!D42<>"",'PRODUCTO NACIONAL'!D42,"") -> 1.8 | E27: =IF('PRODUCTO NACIONAL'!H42<>"",'PRODUCTO NACIONAL'!H42,"") -> 3.8 | F27: =IF('PRODUCTO NACIONAL'!F42<>"",'PRODUCTO NACIONAL'!F42,"") -> TAPA ULISES | G27: =IF('PRODUCTO NACIONAL'!E42<>"",'PRODUCTO NACIONAL'!E42,"") -> ABIERTA | H27: =IF('PRODUCTO NACIONAL'!G42<>"",'PRODUCTO NACIONAL'!G42,"") -> KILOS | I27: =IF('PRODUCTO NACIONAL'!T42<>"",'PRODUCTO NACIONAL'!T42,"") -> 3.5 | J27: =IF('PRODUCTO NACIONAL'!U42<>"",'PRODUCTO NACIONAL'!U42,"") -> 9.25 | K27: =IF('PRODUCTO NACIONAL'!V42<>"",'PRODUCTO NACIONAL'!V42,"") -> 9.55 | L27: =IF('PRODUCTO NACIONAL'!W42<>"",'PRODUCTO NACIONAL'!W42,"") -> 9.75
A28: =IF('PRODUCTO NACIONAL'!A30<>"",'PRODUCTO NACIONAL'!A30,"") -> M27 | B28: VIOTO | C28: =IF('PRODUCTO NACIONAL'!C30<>"",'PRODUCTO NACIONAL'!C30,"") -> TELA | D28: =IF('PRODUCTO NACIONAL'!D30<>"",'PRODUCTO NACIONAL'!D30,"") -> 1.5 | E28: =IF('PRODUCTO NACIONAL'!H30<>"",'PRODUCTO NACIONAL'!H30,"") | F28: =IF('PRODUCTO NACIONAL'!F30<>"",'PRODUCTO NACIONAL'!F30,"") -> VIOTO PESADA BLANCA|NEGRO|NARANJA FOSFORESCENTE | G28: =IF('PRODUCTO NACIONAL'!E30<>"",'PRODUCTO NACIONAL'!E30,"") -> ABIERTA | H28: =IF('PRODUCTO NACIONAL'!G30<>"",'PRODUCTO NACIONAL'!G30,"") -> METRO | I28: =IF('PRODUCTO NACIONAL'!W30<>"",'PRODUCTO NACIONAL'!W30,"") -> 3 | J28: =IF('PRODUCTO NACIONAL'!U30<>"",'PRODUCTO NACIONAL'!U30,"") | K28: =IF('PRODUCTO NACIONAL'!V30<>"",'PRODUCTO NACIONAL'!V30,"") | L28: =IF('PRODUCTO NACIONAL'!W30<>"",'PRODUCTO NACIONAL'!W30,"") -> 3
A29: =IF('PRODUCTO NACIONAL'!A41<>"",'PRODUCTO NACIONAL'!A41,"") -> M38 | B29: ZIDAN | C29: =IF('PRODUCTO NACIONAL'!C41<>"",'PRODUCTO NACIONAL'!C41,"") -> TELA | D29: =IF('PRODUCTO NACIONAL'!D41<>"",'PRODUCTO NACIONAL'!D41,"") -> 1.8 | E29: =IF('PRODUCTO NACIONAL'!H41<>"",'PRODUCTO NACIONAL'!H41,"") -> 3.8 | F29: =IF('PRODUCTO NACIONAL'!F41<>"",'PRODUCTO NACIONAL'!F41,"") -> ZIDAN | G29: =IF('PRODUCTO NACIONAL'!E41<>"",'PRODUCTO NACIONAL'!E41,"") -> ABIERTA | H29: =IF('PRODUCTO NACIONAL'!G41<>"",'PRODUCTO NACIONAL'!G41,"") -> KILOS | I29: =IF('PRODUCTO NACIONAL'!T41<>"",'PRODUCTO NACIONAL'!T41,"") -> 3.5 | J29: =IF('PRODUCTO NACIONAL'!U41<>"",'PRODUCTO NACIONAL'!U41,"") -> 9.25 | K29: =IF('PRODUCTO NACIONAL'!V41<>"",'PRODUCTO NACIONAL'!V41,"") -> 9.55 | L29: =IF('PRODUCTO NACIONAL'!W41<>"",'PRODUCTO NACIONAL'!W41,"") -> 9.75
A30: =IF('PRODUCTO NACIONAL'!A7<>"",'PRODUCTO NACIONAL'!A7,"") -> M4 | C30: =IF('PRODUCTO NACIONAL'!C7<>"",'PRODUCTO NACIONAL'!C7,"") -> PAPEL | D30: =IF('PRODUCTO NACIONAL'!D7<>"",'PRODUCTO NACIONAL'!D7,"") -> 1.62X200 | E30: =IF('PRODUCTO NACIONAL'!H7<>"",'PRODUCTO NACIONAL'!H7,"") | F30: =IF('PRODUCTO NACIONAL'!F7<>"",'PRODUCTO NACIONAL'!F7,"") -> Papel de Sublimación 1.62mx200mx70g | G30: =IF('PRODUCTO NACIONAL'!E7<>"",'PRODUCTO NACIONAL'!E7,"") -> ROLLO | H30: =IF('PRODUCTO NACIONAL'!G7<>"",'PRODUCTO NACIONAL'!G7,"") -> ROLLO | I30: =IF('PRODUCTO NACIONAL'!T7<>"",'PRODUCTO NACIONAL'!T7,"") | J30: =IF('PRODUCTO NACIONAL'!U7<>"",'PRODUCTO NACIONAL'!U7,"") -> 64 | K30: =IF('PRODUCTO NACIONAL'!V7<>"",'PRODUCTO NACIONAL'!V7,"") -> 65 | L30: =IF('PRODUCTO NACIONAL'!W7<>"",'PRODUCTO NACIONAL'!W7,"") -> 67
A31: =IF('PRODUCTO NACIONAL'!A8<>"",'PRODUCTO NACIONAL'!A8,"") -> M5 | C31: =IF('PRODUCTO NACIONAL'!C8<>"",'PRODUCTO NACIONAL'!C8,"") -> PAPEL | D31: =IF('PRODUCTO NACIONAL'!D8<>"",'PRODUCTO NACIONAL'!D8,"") -> 1.62X100 | E31: =IF('PRODUCTO NACIONAL'!H8<>"",'PRODUCTO NACIONAL'!H8,"") | F31: =IF('PRODUCTO NACIONAL'!F8<>"",'PRODUCTO NACIONAL'!F8,"") -> Papel de Sublimación 1.62mx100mx90g | G31: =IF('PRODUCTO NACIONAL'!E8<>"",'PRODUCTO NACIONAL'!E8,"") -> ROLLO | H31: =IF('PRODUCTO NACIONAL'!G8<>"",'PRODUCTO NACIONAL'!G8,"") -> ROLLO | I31: =IF('PRODUCTO NACIONAL'!T8<>"",'PRODUCTO NACIONAL'!T8,"") | J31: =IF('PRODUCTO NACIONAL'!U8<>"",'PRODUCTO NACIONAL'!U8,"") -> 48 | K31: =IF('PRODUCTO NACIONAL'!V8<>"",'PRODUCTO NACIONAL'!V8,"") -> 49 | L31: =IF('PRODUCTO NACIONAL'!W8<>"",'PRODUCTO NACIONAL'!W8,"") -> 50
A32: =IF('PRODUCTO NACIONAL'!A9<>"",'PRODUCTO NACIONAL'!A9,"") -> M6 | C32: =IF('PRODUCTO NACIONAL'!C9<>"",'PRODUCTO NACIONAL'!C9,"") -> PAPEL | D32: =IF('PRODUCTO NACIONAL'!D9<>"",'PRODUCTO NACIONAL'!D9,"") -> 1.12X100 | E32: =IF('PRODUCTO NACIONAL'!H9<>"",'PRODUCTO NACIONAL'!H9,"") | F32: =IF('PRODUCTO NACIONAL'!F9<>"",'PRODUCTO NACIONAL'!F9,"") -> Papel de Sublimación 1.12mx100mx90g | G32: =IF('PRODUCTO NACIONAL'!E9<>"",'PRODUCTO NACIONAL'!E9,"") -> ROLLO | H32: =IF('PRODUCTO NACIONAL'!G9<>"",'PRODUCTO NACIONAL'!G9,"") -> ROLLO | I32: =IF('PRODUCTO NACIONAL'!T9<>"",'PRODUCTO NACIONAL'!T9,"") | J32: =IF('PRODUCTO NACIONAL'!U9<>"",'PRODUCTO NACIONAL'!U9,"") -> 30 | K32: =IF('PRODUCTO NACIONAL'!V9<>"",'PRODUCTO NACIONAL'!V9,"") -> 31 | L32: =IF('PRODUCTO NACIONAL'!W9<>"",'PRODUCTO NACIONAL'!W9,"") -> 33
A33: =IF('PRODUCTO NACIONAL'!A13<>"",'PRODUCTO NACIONAL'!A13,"") -> M10 | C33: =IF('PRODUCTO NACIONAL'!C13<>"",'PRODUCTO NACIONAL'!C13,"") -> PAPEL | D33: =IF('PRODUCTO NACIONAL'!D13<>"",'PRODUCTO NACIONAL'!D13,"") -> 1.8X200 | E33: =IF('PRODUCTO NACIONAL'!H13<>"",'PRODUCTO NACIONAL'!H13,"") | F33: =IF('PRODUCTO NACIONAL'!F13<>"",'PRODUCTO NACIONAL'!F13,"") -> Papel de Sublimación 1.80mx200mx70g | G33: =IF('PRODUCTO NACIONAL'!E13<>"",'PRODUCTO NACIONAL'!E13,"") | H33: =IF('PRODUCTO NACIONAL'!G13<>"",'PRODUCTO NACIONAL'!G13,"") -> ROLLO | I33: =IF('PRODUCTO NACIONAL'!T13<>"",'PRODUCTO NACIONAL'!T13,"") | J33: =IF('PRODUCTO NACIONAL'!U13<>"",'PRODUCTO NACIONAL'!U13,"") -> 80 | K33: =IF('PRODUCTO NACIONAL'!V13<>"",'PRODUCTO NACIONAL'!V13,"") -> 81 | L33: =IF('PRODUCTO NACIONAL'!W13<>"",'PRODUCTO NACIONAL'!W13,"") -> 83
A34: =IF('PRODUCTO NACIONAL'!A59<>"",'PRODUCTO NACIONAL'!A59,"") -> M56 | C34: =IF('PRODUCTO NACIONAL'!C59<>"",'PRODUCTO NACIONAL'!C59,"") -> PAPEL | D34: =IF('PRODUCTO NACIONAL'!D59<>"",'PRODUCTO NACIONAL'!D59,"") -> A4 | E34: =IF('PRODUCTO NACIONAL'!H59<>"",'PRODUCTO NACIONAL'!H59,"") | F34: =IF('PRODUCTO NACIONAL'!F59<>"",'PRODUCTO NACIONAL'!F59,"") -> HOJA PAPEL ADHESIVO BON A4 75GR | G34: =IF('PRODUCTO NACIONAL'!E59<>"",'PRODUCTO NACIONAL'!E59,"") -> HOJA | H34: =IF('PRODUCTO NACIONAL'!G59<>"",'PRODUCTO NACIONAL'!G59,"") -> UNIDAD | I34: =IF('PRODUCTO NACIONAL'!T59<>"",'PRODUCTO NACIONAL'!T59,"") | J34: =IF('PRODUCTO NACIONAL'!U59<>"",'PRODUCTO NACIONAL'!U59,"") | K34: =IF('PRODUCTO NACIONAL'!V59<>"",'PRODUCTO NACIONAL'!V59,"") | L34: =IF('PRODUCTO NACIONAL'!W59<>"",'PRODUCTO NACIONAL'!W59,"") -> 0.75
A35: =IF('PRODUCTO NACIONAL'!A71<>"",'PRODUCTO NACIONAL'!A71,"") -> M68 | C35: =IF('PRODUCTO NACIONAL'!C71<>"",'PRODUCTO NACIONAL'!C71,"") -> PAPEL | D35: =IF('PRODUCTO NACIONAL'!D71<>"",'PRODUCTO NACIONAL'!D71,"") -> 1.62X1000 | E35: =IF('PRODUCTO NACIONAL'!H71<>"",'PRODUCTO NACIONAL'!H71,"") | F35: =IF('PRODUCTO NACIONAL'!F71<>"",'PRODUCTO NACIONAL'!F71,"") -> Papel Crakf 1.62m x 1000m x 30g. | G35: =IF('PRODUCTO NACIONAL'!E71<>"",'PRODUCTO NACIONAL'!E71,"") | H35: =IF('PRODUCTO NACIONAL'!G71<>"",'PRODUCTO NACIONAL'!G71,"") -> ROLLO | I35: =IF('PRODUCTO NACIONAL'!T71<>"",'PRODUCTO NACIONAL'!T71,"") | J35: =IF('PRODUCTO NACIONAL'!U71<>"",'PRODUCTO NACIONAL'!U71,"") -> 120 | K35: =IF('PRODUCTO NACIONAL'!V71<>"",'PRODUCTO NACIONAL'!V71,"") -> 121 | L35: =IF('PRODUCTO NACIONAL'!W71<>"",'PRODUCTO NACIONAL'!W71,"") -> 123
A36: =IF('PRODUCTO NACIONAL'!A75<>"",'PRODUCTO NACIONAL'!A75,"") -> M72 | C36: =IF('PRODUCTO NACIONAL'!C75<>"",'PRODUCTO NACIONAL'!C75,"") -> PAPEL | D36: =IF('PRODUCTO NACIONAL'!D75<>"",'PRODUCTO NACIONAL'!D75,"") -> A4 | E36: =IF('PRODUCTO NACIONAL'!H75<>"",'PRODUCTO NACIONAL'!H75,"") | F36: =IF('PRODUCTO NACIONAL'!F75<>"",'PRODUCTO NACIONAL'!F75,"") -> RESMA PAPEL DE SUBLIMACIÓN A4 75GR | G36: =IF('PRODUCTO NACIONAL'!E75<>"",'PRODUCTO NACIONAL'!E75,"") -> HOJA | H36: =IF('PRODUCTO NACIONAL'!G75<>"",'PRODUCTO NACIONAL'!G75,"") -> UNIDAD | I36: =IF('PRODUCTO NACIONAL'!T75<>"",'PRODUCTO NACIONAL'!T75,"") | J36: =IF('PRODUCTO NACIONAL'!U75<>"",'PRODUCTO NACIONAL'!U75,"") | K36: =IF('PRODUCTO NACIONAL'!V75<>"",'PRODUCTO NACIONAL'!V75,"") | L36: =IF('PRODUCTO NACIONAL'!W75<>"",'PRODUCTO NACIONAL'!W75,"") -> 7.5
J37: MAS DE 10 | K37: MAS DE 4 | L37: LITRO
A38: =IF('PRODUCTO NACIONAL'!A6<>"",'PRODUCTO NACIONAL'!A6,"") -> M3 | C38: =IF('PRODUCTO NACIONAL'!C6<>"",'PRODUCTO NACIONAL'!C6,"") -> TINTA | D38: =IF('PRODUCTO NACIONAL'!D6<>"",'PRODUCTO NACIONAL'!D6,"") | E38: =IF('PRODUCTO NACIONAL'!H6<>"",'PRODUCTO NACIONAL'!H6,"") | F38: =IF('PRODUCTO NACIONAL'!F6<>"",'PRODUCTO NACIONAL'!F6,"") -> Tinta Jaz Negra | G38: =IF('PRODUCTO NACIONAL'!E6<>"",'PRODUCTO NACIONAL'!E6,"") | H38: =IF('PRODUCTO NACIONAL'!G6<>"",'PRODUCTO NACIONAL'!G6,"") -> LITRO | I38: =IF('PRODUCTO NACIONAL'!T6<>"",'PRODUCTO NACIONAL'!T6,"") | J38: =IF('PRODUCTO NACIONAL'!U6<>"",'PRODUCTO NACIONAL'!U6,"") -> 27 | K38: =IF('PRODUCTO NACIONAL'!V6<>"",'PRODUCTO NACIONAL'!V6,"") -> 28 | L38: =IF('PRODUCTO NACIONAL'!W6<>"",'PRODUCTO NACIONAL'!W6,"") -> 30
A39: =IF('PRODUCTO NACIONAL'!A72<>"",'PRODUCTO NACIONAL'!A72,"") -> M69 | C39: =IF('PRODUCTO NACIONAL'!C72<>"",'PRODUCTO NACIONAL'!C72,"") -> TINTA | D39: =IF('PRODUCTO NACIONAL'!D72<>"",'PRODUCTO NACIONAL'!D72,"") | E39: =IF('PRODUCTO NACIONAL'!H72<>"",'PRODUCTO NACIONAL'!H72,"") | F39: =IF('PRODUCTO NACIONAL'!F72<>"",'PRODUCTO NACIONAL'!F72,"") -> Tinta Jaz Azul | G39: =IF('PRODUCTO NACIONAL'!E72<>"",'PRODUCTO NACIONAL'!E72,"") | H39: =IF('PRODUCTO NACIONAL'!G72<>"",'PRODUCTO NACIONAL'!G72,"") -> LITRO | I39: =IF('PRODUCTO NACIONAL'!T72<>"",'PRODUCTO NACIONAL'!T72,"") | J39: =IF('PRODUCTO NACIONAL'!U72<>"",'PRODUCTO NACIONAL'!U72,"") -> 27 | K39: =IF('PRODUCTO NACIONAL'!V72<>"",'PRODUCTO NACIONAL'!V72,"") -> 28 | L39: =IF('PRODUCTO NACIONAL'!W72<>"",'PRODUCTO NACIONAL'!W72,"") -> 30
A40: =IF('PRODUCTO NACIONAL'!A73<>"",'PRODUCTO NACIONAL'!A73,"") -> M70 | C40: =IF('PRODUCTO NACIONAL'!C73<>"",'PRODUCTO NACIONAL'!C73,"") -> TINTA | D40: =IF('PRODUCTO NACIONAL'!D73<>"",'PRODUCTO NACIONAL'!D73,"") | E40: =IF('PRODUCTO NACIONAL'!H73<>"",'PRODUCTO NACIONAL'!H73,"") | F40: =IF('PRODUCTO NACIONAL'!F73<>"",'PRODUCTO NACIONAL'!F73,"") -> Tinta Jaz Amarilla | G40: =IF('PRODUCTO NACIONAL'!E73<>"",'PRODUCTO NACIONAL'!E73,"") | H40: =IF('PRODUCTO NACIONAL'!G73<>"",'PRODUCTO NACIONAL'!G73,"") -> LITRO | I40: =IF('PRODUCTO NACIONAL'!T73<>"",'PRODUCTO NACIONAL'!T73,"") | J40: =IF('PRODUCTO NACIONAL'!U73<>"",'PRODUCTO NACIONAL'!U73,"") -> 27 | K40: =IF('PRODUCTO NACIONAL'!V73<>"",'PRODUCTO NACIONAL'!V73,"") -> 28 | L40: =IF('PRODUCTO NACIONAL'!W73<>"",'PRODUCTO NACIONAL'!W73,"") -> 30
...

Sheet SUMINISTROS YUNPAR
A1: SUMINISTROS YUNPAR
A2: ='PRODUCTO NACIONAL'!A3 -> ID | B2: NN | C2: =+'PRODUCTO NACIONAL'!C3 -> TIPO | D2: =+'PRODUCTO NACIONAL'!D3 -> ANCHO | E2: =+'PRODUCTO NACIONAL'!H3 -> RINDE | F2: ='PRODUCTO NACIONAL'!F3 -> DESCRIPCION | G2: =+'PRODUCTO NACIONAL'!E3 -> TUB./ABIERTA | H2: ='PRODUCTO NACIONAL'!G3 -> UNIDAD | I2: ='PRODUCTO NACIONAL'!T3 -> PVP/metro | J2: ='PRODUCTO NACIONAL'!U3 -> PVP KILO|PROMO | K2: ='PRODUCTO NACIONAL'!V3 -> PVP|DOCENA |X4 | L2: ='PRODUCTO NACIONAL'!W3 -> PVP|UNIDAD | M2: 10 KILOS | N2: 5KILOS
J3: MAS DE 10 | K3: MAS DE 3 | L3: ROLLO | M3: ENVIO= $ 2 | N3: ENVIO= $ 3
A4: =IF('PRODUCTO NACIONAL'!A17<>"",'PRODUCTO NACIONAL'!A17,"") -> M14 | B4: ERNEST | C4: =IF('PRODUCTO NACIONAL'!C17<>"",'PRODUCTO NACIONAL'!C17,"") -> TELA | D4: =IF('PRODUCTO NACIONAL'!D17<>"",'PRODUCTO NACIONAL'!D17,"") -> 1.7 | E4: =IF('PRODUCTO NACIONAL'!H17<>"",'PRODUCTO NACIONAL'!H17,"") -> 4.2 | F4: =IF('PRODUCTO NACIONAL'!F17<>"",'PRODUCTO NACIONAL'!F17,"") -> D2002 Rollo Ernest 1.70m x 140gr | G4: =IF('PRODUCTO NACIONAL'!E17<>"",'PRODUCTO NACIONAL'!E17,"") -> ABIERTA | H4: =IF('PRODUCTO NACIONAL'!G17<>"",'PRODUCTO NACIONAL'!G17,"") -> ROLLO | I4: =IF('PRODUCTO NACIONAL'!T17<>"",'PRODUCTO NACIONAL'!T17,"") | J4: =IF('PRODUCTO NACIONAL'!U17<>"",'PRODUCTO NACIONAL'!U17,"") -> 6 | K4: =IF('PRODUCTO NACIONAL'!V17<>"",'PRODUCTO NACIONAL'!V17,"") -> 6.5 | L4: =IF('PRODUCTO NACIONAL'!W17<>"",'PRODUCTO NACIONAL'!W17,"") -> 6.75 | M4: 8 | N4: 8
A5: =IF('PRODUCTO NACIONAL'!A20<>"",'PRODUCTO NACIONAL'!A20,"") -> M17 | B5: JERSEY | C5: =IF('PRODUCTO NACIONAL'!C20<>"",'PRODUCTO NACIONAL'!C20,"") -> TELA | D5: =IF('PRODUCTO NACIONAL'!D20<>"",'PRODUCTO NACIONAL'!D20,"") -> 1.8 | E5: =IF('PRODUCTO NACIONAL'!H20<>"",'PRODUCTO NACIONAL'!H20,"") -> 2.3 | F5: =IF('PRODUCTO NACIONAL'!F20<>"",'PRODUCTO NACIONAL'!F20,"") -> D2008 Rollo Jersy Spandex 1.80m x 275gr | G5: =IF('PRODUCTO NACIONAL'!E20<>"",'PRODUCTO NACIONAL'!E20,"") -> ABIERTA | H5: =IF('PRODUCTO NACIONAL'!G20<>"",'PRODUCTO NACIONAL'!G20,"") -> ROLLO | I5: =IF('PRODUCTO NACIONAL'!T20<>"",'PRODUCTO NACIONAL'!T20,"") | J5: =IF('PRODUCTO NACIONAL'!U20<>"",'PRODUCTO NACIONAL'!U20,"") -> 8 | K5: =IF('PRODUCTO NACIONAL'!V20<>"",'PRODUCTO NACIONAL'!V20,"") -> 8.5 | L5: =IF('PRODUCTO NACIONAL'!W20<>"",'PRODUCTO NACIONAL'!W20,"") -> 8.75 | M5: 9 | N5: 9
A6: =IF('PRODUCTO NACIONAL'!A18<>"",'PRODUCTO NACIONAL'!A18,"") -> M15 | B6: PANAL | C6: =IF('PRODUCTO NACIONAL'!C18<>"",'PRODUCTO NACIONAL'!C18,"") -> TELA | D6: =IF('PRODUCTO NACIONAL'!D18<>"",'PRODUCTO NACIONAL'!D18,"") -> 1.7 | E6: =IF('PRODUCTO NACIONAL'!H18<>"",'PRODUCTO NACIONAL'!H18,"") -> 3.67 | F6: =IF('PRODUCTO NACIONAL'!F18<>"",'PRODUCTO NACIONAL'!F18,"") -> D2006 Rollo Panal 1.70m x 160gr | G6: =IF('PRODUCTO NACIONAL'!E18<>"",'PRODUCTO NACIONAL'!E18,"") -> ABIERTA | H6: =IF('PRODUCTO NACIONAL'!G18<>"",'PRODUCTO NACIONAL'!G18,"") -> ROLLO | I6: =IF('PRODUCTO NACIONAL'!T18<>"",'PRODUCTO NACIONAL'!T18,"") | J6: =IF('PRODUCTO NACIONAL'!U18<>"",'PRODUCTO NACIONAL'!U18,"") -> 6 | K6: =IF('PRODUCTO NACIONAL'!V18<>"",'PRODUCTO NACIONAL'!V18,"") -> 6.5 | L6: =IF('PRODUCTO NACIONAL'!W18<>"",'PRODUCTO NACIONAL'!W18,"") -> 6.75 | M6: 8 | N6: 8
A7: =IF('PRODUCTO NACIONAL'!A19<>"",'PRODUCTO NACIONAL'!A19,"") -> M16 | B7: PIKE DEPORTIVO | C7: =IF('PRODUCTO NACIONAL'!C19<>"",'PRODUCTO NACIONAL'!C19,"") -> TELA | D7: =IF('PRODUCTO NACIONAL'!D19<>"",'PRODUCTO NACIONAL'!D19,"") -> 1.7 | E7: =IF('PRODUCTO NACIONAL'!H19<>"",'PRODUCTO NACIONAL'!H19,"") -> 3.92 | F7: =IF('PRODUCTO NACIONAL'!F19<>"",'PRODUCTO NACIONAL'!F19,"") -> D2003 Rollo Pike Deportivo 1.70m x 160gr | G7: =IF('PRODUCTO NACIONAL'!E19<>"",'PRODUCTO NACIONAL'!E19,"") -> ABIERTA | H7: =IF('PRODUCTO NACIONAL'!G19<>"",'PRODUCTO NACIONAL'!G19,"") -> ROLLO | I7: =IF('PRODUCTO NACIONAL'!T19<>"",'PRODUCTO NACIONAL'!T19,"") | J7: =IF('PRODUCTO NACIONAL'!U19<>"",'PRODUCTO NACIONAL'!U19,"") -> 6 | K7: =IF('PRODUCTO NACIONAL'!V19<>"",'PRODUCTO NACIONAL'!V19,"") -> 6.5 | L7: =IF('PRODUCTO NACIONAL'!W19<>"",'PRODUCTO NACIONAL'!W19,"") -> 6.75
A8: =IF('PRODUCTO NACIONAL'!A7<>"",'PRODUCTO NACIONAL'!A7,"") -> M4 | C8: =IF('PRODUCTO NACIONAL'!C7<>"",'PRODUCTO NACIONAL'!C7,"") -> PAPEL | D8: =IF('PRODUCTO NACIONAL'!D7<>"",'PRODUCTO NACIONAL'!D7,"") -> 1.62X200 | E8: =IF('PRODUCTO NACIONAL'!H7<>"",'PRODUCTO NACIONAL'!H7,"") | F8: =IF('PRODUCTO NACIONAL'!F7<>"",'PRODUCTO NACIONAL'!F7,"") -> Papel de Sublimación 1.62mx200mx70g | G8: =IF('PRODUCTO NACIONAL'!E7<>"",'PRODUCTO NACIONAL'!E7,"") -> ROLLO | H8: =IF('PRODUCTO NACIONAL'!G7<>"",'PRODUCTO NACIONAL'!G7,"") -> ROLLO | I8: =IF('PRODUCTO NACIONAL'!T7<>"",'PRODUCTO NACIONAL'!T7,"") | J8: =IF('PRODUCTO NACIONAL'!U7<>"",'PRODUCTO NACIONAL'!U7,"") -> 64 | K8: =IF('PRODUCTO NACIONAL'!V7<>"",'PRODUCTO NACIONAL'!V7,"") -> 65 | L8: =IF('PRODUCTO NACIONAL'!W7<>"",'PRODUCTO NACIONAL'!W7,"") -> 67
A9: =IF('PRODUCTO NACIONAL'!A8<>"",'PRODUCTO NACIONAL'!A8,"") -> M5 | C9: =IF('PRODUCTO NACIONAL'!C8<>"",'PRODUCTO NACIONAL'!C8,"") -> PAPEL | D9: =IF('PRODUCTO NACIONAL'!D8<>"",'PRODUCTO NACIONAL'!D8,"") -> 1.62X100 | E9: =IF('PRODUCTO NACIONAL'!H8<>"",'PRODUCTO NACIONAL'!H8,"") | F9: =IF('PRODUCTO NACIONAL'!F8<>"",'PRODUCTO NACIONAL'!F8,"") -> Papel de Sublimación 1.62mx100mx90g | G9: =IF('PRODUCTO NACIONAL'!E8<>"",'PRODUCTO NACIONAL'!E8,"") -> ROLLO | H9: =IF('PRODUCTO NACIONAL'!G8<>"",'PRODUCTO NACIONAL'!G8,"") -> ROLLO | I9: =IF('PRODUCTO NACIONAL'!T8<>"",'PRODUCTO NACIONAL'!T8,"") | J9: =IF('PRODUCTO NACIONAL'!U8<>"",'PRODUCTO NACIONAL'!U8,"") -> 48 | K9: =IF('PRODUCTO NACIONAL'!V8<>"",'PRODUCTO NACIONAL'!V8,"") -> 49 | L9: =IF('PRODUCTO NACIONAL'!W8<>"",'PRODUCTO NACIONAL'!W8,"") -> 50
A10: =IF('PRODUCTO NACIONAL'!A9<>"",'PRODUCTO NACIONAL'!A9,"") -> M6 | C10: =IF('PRODUCTO NACIONAL'!C9<>"",'PRODUCTO NACIONAL'!C9,"") -> PAPEL | D10: =IF('PRODUCTO NACIONAL'!D9<>"",'PRODUCTO NACIONAL'!D9,"") -> 1.12X100 | E10: =IF('PRODUCTO NACIONAL'!H9<>"",'PRODUCTO NACIONAL'!H9,"") | F10: =IF('PRODUCTO NACIONAL'!F9<>"",'PRODUCTO NACIONAL'!F9,"") -> Papel de Sublimación 1.12mx100mx90g | G10: =IF('PRODUCTO NACIONAL'!E9<>"",'PRODUCTO NACIONAL'!E9,"") -> ROLLO | H10: =IF('PRODUCTO NACIONAL'!G9<>"",'PRODUCTO NACIONAL'!G9,"") -> ROLLO | I10: =IF('PRODUCTO NACIONAL'!T9<>"",'PRODUCTO NACIONAL'!T9,"") | J10: =IF('PRODUCTO NACIONAL'!U9<>"",'PRODUCTO NACIONAL'!U9,"") -> 30 | K10: =IF('PRODUCTO NACIONAL'!V9<>"",'PRODUCTO NACIONAL'!V9,"") -> 31 | L10: =IF('PRODUCTO NACIONAL'!W9<>"",'PRODUCTO NACIONAL'!W9,"") -> 33
A11: =IF('PRODUCTO NACIONAL'!A13<>"",'PRODUCTO NACIONAL'!A13,"") -> M10 | C11: =IF('PRODUCTO NACIONAL'!C13<>"",'PRODUCTO NACIONAL'!C13,"") -> PAPEL | D11: =IF('PRODUCTO NACIONAL'!D13<>"",'PRODUCTO NACIONAL'!D13,"") -> 1.8X200 | E11: =IF('PRODUCTO NACIONAL'!H13<>"",'PRODUCTO NACIONAL'!H13,"") | F11: =IF('PRODUCTO NACIONAL'!F13<>"",'PRODUCTO NACIONAL'!F13,"") -> Papel de Sublimación 1.80mx200mx70g | G11: =IF('PRODUCTO NACIONAL'!E13<>"",'PRODUCTO NACIONAL'!E13,"") | H11: =IF('PRODUCTO NACIONAL'!G13<>"",'PRODUCTO NACIONAL'!G13,"") -> ROLLO | I11: =IF('PRODUCTO NACIONAL'!T13<>"",'PRODUCTO NACIONAL'!T13,"") | J11: =IF('PRODUCTO NACIONAL'!U13<>"",'PRODUCTO NACIONAL'!U13,"") -> 80 | K11: =IF('PRODUCTO NACIONAL'!V13<>"",'PRODUCTO NACIONAL'!V13,"") -> 81 | L11: =IF('PRODUCTO NACIONAL'!W13<>"",'PRODUCTO NACIONAL'!W13,"") -> 83
A12: =IF('PRODUCTO NACIONAL'!A71<>"",'PRODUCTO NACIONAL'!A71,"") -> M68 | C12: =IF('PRODUCTO NACIONAL'!C71<>"",'PRODUCTO NACIONAL'!C71,"") -> PAPEL | D12: =IF('PRODUCTO NACIONAL'!D71<>"",'PRODUCTO NACIONAL'!D71,"") -> 1.62X1000 | E12: =IF('PRODUCTO NACIONAL'!H71<>"",'PRODUCTO NACIONAL'!H71,"") | F12: =IF('PRODUCTO NACIONAL'!F71<>"",'PRODUCTO NACIONAL'!F71,"") -> Papel Crakf 1.62m x 1000m x 30g. | G12: =IF('PRODUCTO NACIONAL'!E71<>"",'PRODUCTO NACIONAL'!E71,"") | H12: =IF('PRODUCTO NACIONAL'!G71<>"",'PRODUCTO NACIONAL'!G71,"") -> ROLLO | I12: =IF('PRODUCTO NACIONAL'!T71<>"",'PRODUCTO NACIONAL'!T71,"") | J12: =IF('PRODUCTO NACIONAL'!U71<>"",'PRODUCTO NACIONAL'!U71,"") -> 120 | K12: =IF('PRODUCTO NACIONAL'!V71<>"",'PRODUCTO NACIONAL'!V71,"") -> 121 | L12: =IF('PRODUCTO NACIONAL'!W71<>"",'PRODUCTO NACIONAL'!W71,"") -> 123
A13: =IF('PRODUCTO NACIONAL'!A75<>"",'PRODUCTO NACIONAL'!A75,"") -> M72 | C13: =IF('PRODUCTO NACIONAL'!C75<>"",'PRODUCTO NACIONAL'!C75,"") -> PAPEL | D13: =IF('PRODUCTO NACIONAL'!D75<>"",'PRODUCTO NACIONAL'!D75,"") -> A4 | E13: =IF('PRODUCTO NACIONAL'!H75<>"",'PRODUCTO NACIONAL'!H75,"") | F13: =IF('PRODUCTO NACIONAL'!F75<>"",'PRODUCTO NACIONAL'!F75,"") -> RESMA PAPEL DE SUBLIMACIÓN A4 75GR | G13: =IF('PRODUCTO NACIONAL'!E75<>"",'PRODUCTO NACIONAL'!E75,"") -> HOJA | H13: =IF('PRODUCTO NACIONAL'!G75<>"",'PRODUCTO NACIONAL'!G75,"") -> UNIDAD | I13: =IF('PRODUCTO NACIONAL'!T75<>"",'PRODUCTO NACIONAL'!T75,"") | J13: =IF('PRODUCTO NACIONAL'!U75<>"",'PRODUCTO NACIONAL'!U75,"") | K13: =IF('PRODUCTO NACIONAL'!V75<>"",'PRODUCTO NACIONAL'!V75,"") | L13: =IF('PRODUCTO NACIONAL'!W75<>"",'PRODUCTO NACIONAL'!W75,"") -> 7.5
J14: MAS DE 10 | K14: MAS DE 4 | L14: LITRO
A15: =IF('PRODUCTO NACIONAL'!A6<>"",'PRODUCTO NACIONAL'!A6,"") -> M3 | C15: =IF('PRODUCTO NACIONAL'!C6<>"",'PRODUCTO NACIONAL'!C6,"") -> TINTA | D15: =IF('PRODUCTO NACIONAL'!D6<>"",'PRODUCTO NACIONAL'!D6,"") | E15: =IF('PRODUCTO NACIONAL'!H6<>"",'PRODUCTO NACIONAL'!H6,"") | F15: =IF('PRODUCTO NACIONAL'!F6<>"",'PRODUCTO NACIONAL'!F6,"") -> Tinta Jaz Negra | G15: =IF('PRODUCTO NACIONAL'!E6<>"",'PRODUCTO NACIONAL'!E6,"") | H15: =IF('PRODUCTO NACIONAL'!G6<>"",'PRODUCTO NACIONAL'!G6,"") -> LITRO | I15: =IF('PRODUCTO NACIONAL'!T6<>"",'PRODUCTO NACIONAL'!T6,"") | J15: =IF('PRODUCTO NACIONAL'!U6<>"",'PRODUCTO NACIONAL'!U6,"") -> 27 | K15: =IF('PRODUCTO NACIONAL'!V6<>"",'PRODUCTO NACIONAL'!V6,"") -> 28 | L15: =IF('PRODUCTO NACIONAL'!W6<>"",'PRODUCTO NACIONAL'!W6,"") -> 30
A16: =IF('PRODUCTO NACIONAL'!A72<>"",'PRODUCTO NACIONAL'!A72,"") -> M69 | C16: =IF('PRODUCTO NACIONAL'!C72<>"",'PRODUCTO NACIONAL'!C72,"") -> TINTA | D16: =IF('PRODUCTO NACIONAL'!D72<>"",'PRODUCTO NACIONAL'!D72,"") | E16: =IF('PRODUCTO NACIONAL'!H72<>"",'PRODUCTO NACIONAL'!H72,"") | F16: =IF('PRODUCTO NACIONAL'!F72<>"",'PRODUCTO NACIONAL'!F72,"") -> Tinta Jaz Azul | G16: =IF('PRODUCTO NACIONAL'!E72<>"",'PRODUCTO NACIONAL'!E72,"") | H16: =IF('PRODUCTO NACIONAL'!G72<>"",'PRODUCTO NACIONAL'!G72,"") -> LITRO | I16: =IF('PRODUCTO NACIONAL'!T72<>"",'PRODUCTO NACIONAL'!T72,"") | J16: =IF('PRODUCTO NACIONAL'!U72<>"",'PRODUCTO NACIONAL'!U72,"") -> 27 | K16: =IF('PRODUCTO NACIONAL'!V72<>"",'PRODUCTO NACIONAL'!V72,"") -> 28 | L16: =IF('PRODUCTO NACIONAL'!W72<>"",'PRODUCTO NACIONAL'!W72,"") -> 30
A17: =IF('PRODUCTO NACIONAL'!A73<>"",'PRODUCTO NACIONAL'!A73,"") -> M70 | C17: =IF('PRODUCTO NACIONAL'!C73<>"",'PRODUCTO NACIONAL'!C73,"") -> TINTA | D17: =IF('PRODUCTO NACIONAL'!D73<>"",'PRODUCTO NACIONAL'!D73,"") | E17: =IF('PRODUCTO NACIONAL'!H73<>"",'PRODUCTO NACIONAL'!H73,"") | F17: =IF('PRODUCTO NACIONAL'!F73<>"",'PRODUCTO NACIONAL'!F73,"") -> Tinta Jaz Amarilla | G17: =IF('PRODUCTO NACIONAL'!E73<>"",'PRODUCTO NACIONAL'!E73,"") | H17: =IF('PRODUCTO NACIONAL'!G73<>"",'PRODUCTO NACIONAL'!G73,"") -> LITRO | I17: =IF('PRODUCTO NACIONAL'!T73<>"",'PRODUCTO NACIONAL'!T73,"") | J17: =IF('PRODUCTO NACIONAL'!U73<>"",'PRODUCTO NACIONAL'!U73,"") -> 27 | K17: =IF('PRODUCTO NACIONAL'!V73<>"",'PRODUCTO NACIONAL'!V73,"") -> 28 | L17: =IF('PRODUCTO NACIONAL'!W73<>"",'PRODUCTO NACIONAL'!W73,"") -> 30
A18: =IF('PRODUCTO NACIONAL'!A74<>"",'PRODUCTO NACIONAL'!A74,"") -> M71 | C18: =IF('PRODUCTO NACIONAL'!C74<>"",'PRODUCTO NACIONAL'!C74,"") -> TINTA | D18: =IF('PRODUCTO NACIONAL'!D74<>"",'PRODUCTO NACIONAL'!D74,"") | E18: =IF('PRODUCTO NACIONAL'!H74<>"",'PRODUCTO NACIONAL'!H74,"") | F18: =IF('PRODUCTO NACIONAL'!F74<>"",'PRODUCTO NACIONAL'!F74,"") -> Tinta Jaz Roja | G18: =IF('PRODUCTO NACIONAL'!E74<>"",'PRODUCTO NACIONAL'!E74,"") | H18: =IF('PRODUCTO NACIONAL'!G74<>"",'PRODUCTO NACIONAL'!G74,"") -> LITRO | I18: =IF('PRODUCTO NACIONAL'!T74<>"",'PRODUCTO NACIONAL'!T74,"") | J18: =IF('PRODUCTO NACIONAL'!U74<>"",'PRODUCTO NACIONAL'!U74,"") -> 27 | K18: =IF('PRODUCTO NACIONAL'!V74<>"",'PRODUCTO NACIONAL'!V74,"") -> 28 | L18: =IF('PRODUCTO NACIONAL'!W74<>"",'PRODUCTO NACIONAL'!W74,"") -> 30
A20: =IF('PRODUCTO NACIONAL'!A76<>"",'PRODUCTO NACIONAL'!A76,"") -> M73 | C20: =IF('PRODUCTO NACIONAL'!C76<>"",'PRODUCTO NACIONAL'!C76,"") -> CINTA | D20: =IF('PRODUCTO NACIONAL'!D76<>"",'PRODUCTO NACIONAL'!D76,"") -> 3cm | E20: =IF('PRODUCTO NACIONAL'!H76<>"",'PRODUCTO NACIONAL'!H76,"") | F20: =IF('PRODUCTO NACIONAL'!F76<>"",'PRODUCTO NACIONAL'!F76,"") -> CINTA REFLECTIVA DE 3cm de anchox1m | G20: =IF('PRODUCTO NACIONAL'!E76<>"",'PRODUCTO NACIONAL'!E76,"") -> CINTA | H20: =IF('PRODUCTO NACIONAL'!G76<>"",'PRODUCTO NACIONAL'!G76,"") -> UNIDAD | I20: =IF('PRODUCTO NACIONAL'!T76<>"",'PRODUCTO NACIONAL'!T76,"") | J20: =IF('PRODUCTO NACIONAL'!U76<>"",'PRODUCTO NACIONAL'!U76,"") | K20: =IF('PRODUCTO NACIONAL'!V76<>"",'PRODUCTO NACIONAL'!V76,"") | L20: =IF('PRODUCTO NACIONAL'!W76<>"",'PRODUCTO NACIONAL'!W76,"")
A21: =IF('PRODUCTO NACIONAL'!A79<>"",'PRODUCTO NACIONAL'!A79,"") -> M79 | C21: =IF('PRODUCTO NACIONAL'!C79<>"",'PRODUCTO NACIONAL'!C79,"") -> CINTA | D21: =IF('PRODUCTO NACIONAL'!D79<>"",'PRODUCTO NACIONAL'!D79,"") -> 1cm | E21: =IF('PRODUCTO NACIONAL'!H79<>"",'PRODUCTO NACIONAL'!H79,"") | F21: =IF('PRODUCTO NACIONAL'!F79<>"",'PRODUCTO NACIONAL'!F79,"") -> CINTA TERMICA | G21: =IF('PRODUCTO NACIONAL'!E79<>"",'PRODUCTO NACIONAL'!E79,"") | H21: =IF('PRODUCTO NACIONAL'!G79<>"",'PRODUCTO NACIONAL'!G79,"") -> UNIDAD | I21: =IF('PRODUCTO NACIONAL'!T79<>"",'PRODUCTO NACIONAL'!T79,"") | J21: =IF('PRODUCTO NACIONAL'!U79<>"",'PRODUCTO NACIONAL'!U79,"") -> 2.5 | K21: =IF('PRODUCTO NACIONAL'!V79<>"",'PRODUCTO NACIONAL'!V79,"") -> 2.75 | L21: =IF('PRODUCTO NACIONAL'!W79<>"",'PRODUCTO NACIONAL'!W79,"") -> 3
I22: 100METROS | J22: 50 METROS | K22: 10 METROS | L22: 1 METRO
A23: =IF('PRODUCTO NACIONAL'!A14<>"",'PRODUCTO NACIONAL'!A14,"") -> M11 | C23: =IF('PRODUCTO NACIONAL'!C14<>"",'PRODUCTO NACIONAL'!C14,"") -> IMPRESIÓN | D23: =IF('PRODUCTO NACIONAL'!D14<>"",'PRODUCTO NACIONAL'!D14,"") -> 1.8 | E23: =IF('PRODUCTO NACIONAL'!H14<>"",'PRODUCTO NACIONAL'!H14,"") | F23: =IF('PRODUCTO NACIONAL'!F14<>"",'PRODUCTO NACIONAL'!F14,"") -> IMPRESIÓN SIN DISEÑO, ANCHO 1.8X90gsm | G23: =IF('PRODUCTO NACIONAL'!E14<>"",'PRODUCTO NACIONAL'!E14,"") -> ROLLO | H23: =IF('PRODUCTO NACIONAL'!G14<>"",'PRODUCTO NACIONAL'!G14,"") -> METRO | I23: 3.15 | J23: =IF('PRODUCTO NACIONAL'!U14<>"",'PRODUCTO NACIONAL'!U14,"") -> 3.25 | K23: =IF('PRODUCTO NACIONAL'!V14<>"",'PRODUCTO NACIONAL'!V14,"") -> 3.4 | L23: =IF('PRODUCTO NACIONAL'!W14<>"",'PRODUCTO NACIONAL'!W14,"") -> 3.5
A24: =IF('PRODUCTO NACIONAL'!A29<>"",'PRODUCTO NACIONAL'!A29,"") -> M26 | C24: =IF('PRODUCTO NACIONAL'!C29<>"",'PRODUCTO NACIONAL'!C29,"") -> IMPRESIÓN | D24: =IF('PRODUCTO NACIONAL'!D29<>"",'PRODUCTO NACIONAL'!D29,"") -> 1.12 | E24: =IF('PRODUCTO NACIONAL'!H29<>"",'PRODUCTO NACIONAL'!H29,"") | F24: =IF('PRODUCTO NACIONAL'!F29<>"",'PRODUCTO NACIONAL'!F29,"") -> IMPRESIÓN SIN DISEÑO, ANCHO 1.12mX90gsm | G24: =IF('PRODUCTO NACIONAL'!E29<>"",'PRODUCTO NACIONAL'!E29,"") | H24: =IF('PRODUCTO NACIONAL'!G29<>"",'PRODUCTO NACIONAL'!G29,"") -> METRO | I24: 2.4 | J24: =IF('PRODUCTO NACIONAL'!U29<>"",'PRODUCTO NACIONAL'!U29,"") -> 2.5 | K24: =IF('PRODUCTO NACIONAL'!V29<>"",'PRODUCTO NACIONAL'!V29,"") -> 2.65 | L24: =IF('PRODUCTO NACIONAL'!W29<>"",'PRODUCTO NACIONAL'!W29,"") -> 2.75
A25: =IF('PRODUCTO NACIONAL'!A35<>"",'PRODUCTO NACIONAL'!A35,"") -> M32 | C25: =IF('PRODUCTO NACIONAL'!C35<>"",'PRODUCTO NACIONAL'!C35,"") -> IMPRESIÓN | D25: =IF('PRODUCTO NACIONAL'!D35<>"",'PRODUCTO NACIONAL'!D35,"") -> 1.62 | E25: =IF('PRODUCTO NACIONAL'!H35<>"",'PRODUCTO NACIONAL'!H35,"") | F25: =IF('PRODUCTO NACIONAL'!F35<>"",'PRODUCTO NACIONAL'!F35,"") -> IMPRESIÓN SIN DISEÑO, ANCHO 1.62mX70gsm | G25: =IF('PRODUCTO NACIONAL'!E35<>"",'PRODUCTO NACIONAL'!E35,"") | H25: =IF('PRODUCTO NACIONAL'!G35<>"",'PRODUCTO NACIONAL'!G35,"") -> METRO | I25: 3 | J25: =IF('PRODUCTO NACIONAL'!U35<>"",'PRODUCTO NACIONAL'!U35,"") -> 3.1 | K25: =IF('PRODUCTO NACIONAL'!V35<>"",'PRODUCTO NACIONAL'!V35,"") -> 3.25 | L25: =IF('PRODUCTO NACIONAL'!W35<>"",'PRODUCTO NACIONAL'!W35,"") -> 3.35
